Workbook
Name a: #N/A
Name aa: #N/A
Name aaa: #REF!
Name aaa: #REF!
Name AC: #REF!
Name AD: #REF!
Name Addr1: "台北市內湖路一段308號4樓 "
Name Addr2: "Tel: 02-27973357 Fax: 02-7973957"
Name AFASDF: #REF!
Name AFASDF: #REF!
Name Agent: "莊順裕"
Name AgentTitle: " "
Name b: #N/A
Name bb: #N/A
Name Bill: ""
Name BillTo1: " "
Name Check: ""
Name ChineseAmt: "參仟伍佰萬元整"
Name CIM_MESSAGE: #REF!
Name CIM_MESSAGE: #REF!
Name Clerk: "柯秋君 "
Name Common_HS_Index: #REF!
Name Common_HS_Index: #REF!
Name Company: "德技股份有限公司"
Name COMPONENT시점: #N/A
Name CST_Command: #REF!
Name CST_Command: #REF!
Name CST_Data_Upload: '[1]LD_ULD Special Handshake'!#REF!
Name CST_Data_Upload: '[1]LD_ULD Special Handshake'!#REF!
Name CST_Empty_Indicate_For_Unloader: #REF!
Name CST_Empty_Indicate_For_Unloader: #REF!
Name Currency: "日圓 1:0.4071"
Name CurrencyName: "日圓"
Name CurrencyText: "幣別匯率："
Name Cust1: ""
Name Cust2: ""
Name CustName1: ""
Name CustName2: ""
Name CustomNo: ""
Name Daily_Glass: #REF!
Name Daily_Glass: #REF!
Name Daily_Limit_Slot_cmd: #REF!
Name Daily_Limit_Slot_cmd: #REF!
Name Date: "2004 年 1 月 15 日"
Name Date_Time_Calibration_Handshake: #REF!
Name Date_Time_Calibration_Handshake: #REF!
Name dd: #N/A
Name Depot: ""
Name DepotLst: ""
Name DFF: #REF!
Name DFF: #REF!
Name Dispatch: #REF!
Name Dispatch: #REF!
Name Down_Status_Alarm_Code_Rpt: #REF!
Name Down_Status_Alarm_Code_Rpt: #REF!
Name Drawing: OFFSET(#REF!,'2.Master List 작성(업체 작성 SHEET)'!이차,'2.Master List 작성(업체 작성 SHEET)'!스크롤,1,13)
Name Drawing: OFFSET(#REF!,[0]!이차,[0]!스크롤,1,13)
Name Drawing_Sample: OFFSET(#REF!,'2.Master List 작성(업체 작성 SHEET)'!이차,'2.Master List 작성(업체 작성 SHEET)'!스크롤,1,13)
Name Drawing_Sample: OFFSET(#REF!,[0]!이차,[0]!스크롤,1,13)
Name Drawing2: OFFSET(#REF!,'2.Master List 작성(업체 작성 SHEET)'!이차,'2.Master List 작성(업체 작성 SHEET)'!스크롤,1,13)

Sheet Main
L1: Samsung Display Confidential

Sheet 변경이력
G1: Samsung Display Confidential
B2: NO | C2: REVISION | D2: 변경내용 | E2: 변경일자 | F2: 변경요청자 | G2: 수정자
B3: 1 | C3: 1.0.0 | D3: 사양 배포 | E3: 41983 | F3: 홍길동 | G3: 홍길동
B4: 2 | C4: 1.9.1 | D4: ACTION NAME : RETRY → TRY 변경 | E4: 44953 | F4: 성열태 | G4: 성열태
D5: ACT_WAIT_TIME 추가 | E5: 44953 | F5: 성열태 | G5: 이승호
D6: CV 물류 작성 방법 추가 | E6: 44953 | F6: 성열태 | G6: 성열태
B7: 3 | C7: 1.9.1 | D7: SYSTEM No 1A01~ 시작, CYCLE 1A10 ~ 시작 , 1Z99 > 2A01 > 2A02 | E7: 45063 | F7: 성열태 | G7: 성열태
B8: 4 | C8: 1.9.2 | D8: 4_1(참조) Master List 작성 방법 예시 Sheet, 작성 예시 내용 수정 | E8: 45211 | F8: 성열태 | G8: 성열태
B9: 5 | C9: 1.9.3 | D9: 4_1(참조) Master List 작성 방법 예시 Sheet | E9: 45447 | F9: 성열태 | G9: 성열태
D10: COMPONENT_IN/OUT : "GET", "PUT" 추가, NG 항목 내용 추가 | E10: 45447 | F10: 성열태 | G10: 성열태
D11: ACTION NAME : MOVE_WAIT_POS 축 분리
D12: TRAY, 자재 물류 IN/OUT_WAIT_TIME 기준 수정 및 추가
D13: LMS 물류 기준 추가
D14: SINGLE : MODID_ALARM, MODID_ALARM_STOP 추가
C15: 1.9.3 | D15: 4_2(참조) 시점 정의 예시 Sheet | E15: 45447 | F15: 성열태 | G15: 성열태
D16: AUTO_CYCLE 시점 정의(TRANSFER 제외) 삭제
D17: Ready Cycle STEP 정의 삭제
D18: INITIAL STEP 시점 정의(중복) 삭제
C19: 1.9.3 | D19: 4_3(참조) IN_OUT 시점 정의 예시 Sheet | E19: 45447 | F19: 성열태 | G19: 성열태
D20: 5 검사 PROCESS 및 VISION PROCESS MCC 예시 수정 및 추가
C21: 1.9.3 | D21: 4_1(참조) Master List 작성 방법 예시 Sheet | E21: 45476 | F21: 성열태 | G21: 성열태
D22: 19. CV 물류 CV 이동 동작 SINGLE 카테고리 작성 문구 삭제
C23: 간소화 | D23: Signal Log 입력란 삭제 | E23: 45776 | F23: 최경민 | G23: 최경민
D24: 4. Master List작성
D25: SIGNAL LOG AREA 삭제
D26: 4_1.(참조) Master List 작성 방법 예시
D27: SIGNAL, INFORMATION, ERROR/WARNING, EVENT LOG AREA 삭제
D28: 6. Host전송 Sheet 삭제
D29: 기준정보 입력 Sheet A,S,V,I 삭제
C30: 1.9.4 | D30: 4. Master List작성 SHEET | E30: 45803 | F30: 성열태 | G30: 성열태
D31: ACTION LOG AREA 표 구분란 2줄 → 1줄 수정
D32: SystemNo+ActionName (서식 有) : "글자수 기준 : 50자" 기준 추가
C33: 2.0.0 | D33: 효율화 작업 적용 | E33: 45821 | F33: 최경민 | G33: 최경민
D34: Check Sheet 신규 생성
D35: 각종 검수 확인 Sheet Check List Sheet로 통합
D36: 검수 효율화 관련 검수 항목별 투자부서 , 제조혁신 책임 구분
D37: 각종 검수 확인 Sheet Check List Sheet로 통합

Sheet Check Sheet
P2: Samsung Display Confidential
B3: Maker | C3: Maker 명
C4: EQP ID
C5: Maker담당자 | O5: =86/3 -> 28.666667
C6: Maker연락처
Q7: =256000*3 -> 768000
B8: ※ 하기의 모든 List가 OK처리가 되어 진척율 100%를 달성해야지만 MCC의 모든 Set Up이 종료 및 최종 승인 된다.
B9: Warranty 기간이 지났음에도 불구하고 , Check List 모든 항목에 OK 처리가 되어있지 않으면, 이는 Maker측 셋업 및 대응 미흡으로 간주하고 OK 시까지무상 대응해야한다.
B11: 진행율 | D11: =COUNT(L15:L28)/14 -> 0
B13: 셋업구분 | C13: No | D13: MCC Set Up Process | J13: 책임 부서 | L13: 완료일정 | M13: 판정 | N13: 담당자 | O13: 증빙자료 캡쳐본 첨부 | P13: EqVerse
J14: 투자부서 (기술팀,개발팀..) | K14: 제조혁신
B15: DR | C15: 1 | D15: ■ MCC 사양서 및 Master List 배포 - EqVerse에 등록된 자료 활용 (최신 Ver. 관리 _ 제조혁신) | K15: ● | M15: OK / NG | O15: - | P15: DR결과 등록 (투자부서 상신)
C16: 2 | D16: ■ DR 일정 협의 - 신규,개조,Repeat 설비등 제작 사양에 따라 대면 DR 진행 여부 판단 | J16: ● | M16: OK / NG
C17: 3 | D17: ■ MCC 사양 협의 (DR 진행) - 제조 혁신,투자부서(기술팀,개발팀..),설비 Maker MCC 적용협의 | J17: ● | K17: ● | M17: OK / NG | O17: -DR회의록 캡쳐본 첨부-
B18: 제작검수 | C18: 4 | D18: ■ MCC Master List 초안 제출 (Action Log 만 적용) - 업체 제어 담당자 작성 후 투자부서(기술팀,개발팀..)에서 작성 된 설비 동작 순서 와 실제 설비 동작이 맞는지 검증 진행 - 동작 순서 검증 후 제조혁신 담당자에게 Master List 제출 | J18: ● | M18: OK / NG | O18: - | P18: 제작 검수_MCC (제조혁신 상신)
C19: 5 | D19: ■ Master List 검증 - Master List 작성 규칙 검증 | K19: ● | M19: OK / NG | O19: -
C20: 6 | D20: ■ MCC Master List 확정 - 기술팀 : Master List에 작성된 설비 동작 순서 검증 완료 時 제조혁신 : Master List 작성 규칙 검증 완료 時 | K20: ● | M20: OK / NG | O20: -
C21: 7 | D21: ■ MCC T-Log 생성 - 연속된 2~3개 Unit MCC Log 생성 후 제조혁신 담당자에게 제출 . PC 제어 설비 : 업체 자체 Program으로 Log 생성 . PLC 제어 설비 : 現 미쓰비시 PLC 限 Log 생성 Agent 및 PLC MAP File 제공 미쓰비시 PLC외 타 Maker PLC는 업체 자체 Agent 사용 | J21: ● | M21: OK / NG | O21: -
C22: 8 | D22: ■ MCC T-Log 검증 - MCC Checker Tool T Log A점수 90점 이상 | K22: ● | M22: OK / NG | O22: -MCC Checker 점수 캡쳐본 첨부-
B23: 입고 검수 | C23: 9 | D23: ■ MCC 상위 Host FTP 데이터 전송 - File 생성 , FTP Upload 주기 확인 (주기 설정 가능 여부 확인) - 지정 경로 , FTP ID,Password 제조혁신 제공 | J23: ● | M23: OK / NG | O23: -FTP Upload 캡쳐본 첨부- M-MAS Log Download 기능 활용 | P23: 품질 certify_MCC (기술팀 상신)
C24: 10 | D24: ■ Master List 최종 확정 - 제작 검수 이후 동작 수정 여부 확인 . 동작 수정 時 변경내용 반영 후 제조혁신 담당자에게 제출 | J24: ● | M24: OK / NG | O24: -
C25: 11 | D25: ■ MCC T-Log 생성 - Master List에 작성된 모든 동작 Log 생성 - 작업 완료 후 제조혁신 담당자 Inform 실시 | J25: ● | M25: OK / NG
C26: 12 | D26: ■ MCC T-Log 검증 - M-MAS System을 활용 하여 Data 확보 (제조혁신) . MCC Checker Tool T Log A,B 점수 90점 이상 | K26: ● | M26: OK / NG
C27: 13 | D27: ■ Chart 검증 - 설비 전체 동작 Chart 정합성 100% 일치 | K27: ● | M27: OK / NG | O27: -MCC Checker 점수 캡쳐본 첨부-
C28: 14 | D28: ■ MCC 실행 PC D: 드라이브에 MCC 폴더 생성 하여 최종 확정 본 저장 - PC 제어 설비 : Master List - PLC 제어 설비 : Master List , MCC PLC Map File | J28: ● | M28: OK / NG | O28: -저장 폴더 캡쳐본 첨부-

Sheet 1.MCC UI구성
M2: Samsung Display Confidential
L3: [사양서 FTP 참고사항] | S3: [File Path] | W3: [File Path]
L26: ※ T Log , Index File 적용

Sheet 2.Master List 작성(업체 작성 SHEET)
I1: Samsung Display Confidential | P1: Samsung Display Confidential
B2: Maker 명 | C2: TOP Engineering | E2: MCC 담당자/직함 (Maker)
B3: 설비 명 | C3: 치수검사기 | E3: 연락처
B5: ※ 설비 입고전 협의된 일정內에 MCC Master List를 작성 제출해야하며, 입고후 Maker에서는 매주 정합성 자체검증하여 근거자료(MCC Log)와 함께 제출한다.
B6: 1. Modeling
B7: MCC의 모델링은 자재 이동단위로 상세하게 나눈다. - CIM Modeling보다 세분화 시킴
B8: EQP ID | C8: Layer01 | D8: Layer02 | E8: Layer03 | F8: Layer04 | G8: Description
D9: ST01 | G9: Stage Transfer1
D10: ST02 | G10: Stage Transfer2
D11: SH01 | G11: Scan Head1
B15: 2. Layout
B16: 하기 Sample처럼 ModuleID, 구성부품NAME, GLASS이동방향을 표현한다.
B31: 3. Moving Path
B32: 자동운전時 Panel 및 Panel을 포함한 모든자재의 이동경로의 CASE를 나열한다.
B33: CASE | C33: 자재명 | D33: PATH
B34: 1 | C34: Panel Ass'y | D34: ST01, ST02 → SH01 → ST01, ST02
B35: 2
B36: 3
B37: 4
B39: 4. Action Log Area
T40: < MCC Checker 기준정보>
B41: Module ID | C41: Action Category | D41: Sequence No | E41: SystemNo | F41: Log Type ( A ) | G41: Action Name | H41: SystemNo+ActionName (서식 有) | I41: Description | J41: From Position List ModuleID#SlotNo) | K41: To Position List ModuleID#SlotNo) | L41: Expression START | M41: Expression END | N41: STEP Time(Sec) Min(00.0) | O41: STEP Time(Sec Max(00.0) | P41: 로깅 제외대상 | Q41: 검증 제외대상 | R41: 비고 | T41: NO | U41: UnitID | V41: Action Name | W41: 설명 | X41: 보기순서 | Y41: FROM=TO | Z41: 기준MIN | AA41: 기준MAX | AB41: GlassID Pair오류 | AC41: GlassID누락 | AD41: HostPPID누락 | AE41: EqPPID누락 | AF41: LotID누락 | AG41: StepID누락 | AH41: Pair_Slot구분 | AI41: 기준정보 미포함
B42: MAIN | C42: Change | D42: A.1 | E42: 1A01 | F42: A | G42: CHANGE RECIPE | H42: =CONCATENATE(E42,"_",G42) -> 1A01_CHANGE RECIPE | I42: CHANGE RECIPE | J42: MAIN | K42: MAIN | T42: 1 | U42: =IF(B42="",U41,B42) -> MAIN | V42: =H42 -> 1A01_CHANGE RECIPE | W42: =I42 -> CHANGE RECIPE | X42: 1 | Y42: =CONCATENATE(J42,"=",K42) -> MAIN=MAIN | Z42: 0 | AA42: 0 | AB42: Y | AC42: Y | AD42: Y | AE42: Y | AF42: N | AG42: Y | AH42: N | AI42: N
D43: A.2 | E43: 1A02 | F43: A | H43: =CONCATENATE(E43,"_",G43) -> 1A02_ | T43: 2 | U43: =IF(B43="",U42,B43) -> MAIN | V43: =H43 -> 1A02_ | W43: =I43 -> 0 | X43: 2 | Y43: =CONCATENATE(J43,"=",K43) -> = | Z43: 0 | AA43: 0 | AB43: Y | AC43: Y | AD43: Y | AE43: Y | AF43: N | AG43: Y | AH43: N | AI43: N
B44: ST01 | C44: Initial | D44: A.1 | E44: 1A01 | F44: A | G44: STAGE1_ORIGIN | H44: =CONCATENATE(E44,"_",G44) -> 1A01_STAGE1_ORIGIN | I44: STAGE1 원점 동작 | J44: ST01 | K44: ST01 | L44: START | M44: END | N44: Min Time | O44: Max Time | T44: 3 | U44: =IF(B44="",U41,B44) -> ST01 | V44: =H44 -> 1A01_STAGE1_ORIGIN | W44: =I44 -> STAGE1 원점 동작 | X44: 1 | Y44: =CONCATENATE(J44,"=",K44) -> ST01=ST01 | Z44: 0 | AA44: 0 | AB44: Y | AC44: Y | AD44: Y | AE44: Y | AF44: N | AG44: Y | AH44: N | AI44: N
D45: A.1a | E45: 1A02 | F45: A | H45: =CONCATENATE(E45,"_",G45) -> 1A02_ | L45: START | M45: END | T45: 4 | U45: =IF(B45="",U44,B45) -> ST01 | V45: =H45 -> 1A02_ | W45: =I45 -> 0 | X45: 2 | Y45: =CONCATENATE(J45,"=",K45) -> = | Z45: 0 | AA45: 0 | AB45: Y | AC45: Y | AD45: Y | AE45: Y | AF45: N | AG45: Y | AH45: N | AI45: N
C46: Change | D46: A.1 | E46: 1A07 | F46: A | G46: CHANGE_PARAMETER | H46: =CONCATENATE(E46,"_",G46) -> 1A07_CHANGE_PARAMETER | I46: STAGE1 동작 Parameter 변경 | J46: ST01 | K46: ST01 | L46: START | M46: END | T46: 9 | U46: =IF(B46="",#REF!,B46) -> #REF! | V46: =H46 -> 1A07_CHANGE_PARAMETER | W46: =I46 -> STAGE1 동작 Parameter 변경 | X46: 7 | Y46: =CONCATENATE(J46,"=",K46) -> ST01=ST01 | Z46: 0 | AA46: 0 | AB46: Y | AC46: Y | AD46: Y | AE46: Y | AF46: N | AG46: Y | AH46: N | AI46: N
D47: A.1a | E47: 1A08 | F47: A | H47: =CONCATENATE(E47,"_",G47) -> 1A08_ | L47: START | M47: END | T47: 10 | U47: =IF(B47="",U46,B47) -> #REF! | V47: =H47 -> 1A08_ | W47: =I47 -> 0 | X47: 8 | Y47: =CONCATENATE(J47,"=",K47) -> = | Z47: 0 | AA47: 0 | AB47: Y | AC47: Y | AD47: Y | AE47: Y | AF47: N | AG47: Y | AH47: N | AI47: N
C48: Cycle | D48: A.1 | E48: 1A10 | F48: A | G48: WAIT_COMPONENT_IN | H48: =CONCATENATE(E48,"_",G48) -> 1A10_WAIT_COMPONENT_IN | I48: 자재 투입 대기 | J48: ST01 | K48: ST01 | L48: START | M48: END | T48: 12 | U48: =IF(B48="",#REF!,B48) -> #REF! | V48: =H48 -> 1A10_WAIT_COMPONENT_IN | W48: =I48 -> 자재 투입 대기 | X48: 10 | Y48: =CONCATENATE(J48,"=",K48) -> ST01=ST01 | Z48: 0 | AA48: 0 | AB48: Y | AC48: Y | AD48: Y | AE48: Y | AF48: N | AG48: Y | AH48: N | AI48: N
D49: A.2 | E49: 1A11 | F49: A | G49: COMPONENT_IN | H49: =CONCATENATE(E49,"_",G49) -> 1A11_COMPONENT_IN | I49: 자재 투입 | J49: ST01 | K49: ST01 | L49: START | M49: END | T49: 13 | U49: =IF(B49="",U48,B49) -> #REF! | V49: =H49 -> 1A11_COMPONENT_IN | W49: =I49 -> 자재 투입 | X49: 11 | Y49: =CONCATENATE(J49,"=",K49) -> ST01=ST01 | Z49: 0 | AA49: 0 | AB49: Y | AC49: Y | AD49: Y | AE49: Y | AF49: N | AG49: Y | AH49: N | AI49: N
D50: A.2.1 | E50: 1A12 | F50: A | G50: INSPECTION | H50: =CONCATENATE(E50,"_",G50) -> 1A12_INSPECTION | I50: 검사 | J50: ST01 | K50: ST01 | L50: START | M50: END | T50: 14 | U50: =IF(B50="",U49,B50) -> #REF! | V50: =H50 -> 1A12_INSPECTION | W50: =I50 -> 검사 | X50: 12 | Y50: =CONCATENATE(J50,"=",K50) -> ST01=ST01 | Z50: 0 | AA50: 0 | AB50: Y | AC50: Y | AD50: Y | AE50: Y | AF50: N | AG50: Y | AH50: N | AI50: N
D51: A.2.2 | E51: 1A13 | F51: A | G51: WAIT_COMPONENT_OUT | H51: =CONCATENATE(E51,"_",G51) -> 1A13_WAIT_COMPONENT_OUT | I51: 자재 배출 대기 | J51: ST01 | K51: ST01 | L51: START | M51: END | T51: 15 | U51: =IF(B51="",U50,B51) -> #REF! | V51: =H51 -> 1A13_WAIT_COMPONENT_OUT | W51: =I51 -> 자재 배출 대기 | X51: 13 | Y51: =CONCATENATE(J51,"=",K51) -> ST01=ST01 | Z51: 0 | AA51: 0 | AB51: Y | AC51: Y | AD51: Y | AE51: Y | AF51: N | AG51: Y | AH51: N | AI51: N
D52: A2.3 | E52: 1A14 | F52: A | H52: =CONCATENATE(E52,"_",G52) -> 1A14_ | L52: START | M52: END | T52: 16 | U52: =IF(B52="",U51,B52) -> #REF! | V52: =H52 -> 1A14_ | W52: =I52 -> 0 | X52: 14 | Y52: =CONCATENATE(J52,"=",K52) -> = | Z52: 0 | AA52: 0 | AB52: Y | AC52: Y | AD52: Y | AE52: Y | AF52: N | AG52: Y | AH52: N | AI52: N
D53: A.3 | E53: 1A15 | F53: A | H53: =CONCATENATE(E53,"_",G53) -> 1A15_ | L53: START | M53: END | T53: 17 | U53: =IF(B53="",U52,B53) -> #REF! | V53: =H53 -> 1A15_ | W53: =I53 -> 0 | X53: 15 | Y53: =CONCATENATE(J53,"=",K53) -> = | Z53: 0 | AA53: 0 | AB53: Y | AC53: Y | AD53: Y | AE53: Y | AF53: N | AG53: Y | AH53: N | AI53: N
D54: A.4 | E54: 1A16 | F54: A | H54: =CONCATENATE(E54,"_",G54) -> 1A16_ | L54: START | M54: END | T54: 18 | U54: =IF(B54="",U53,B54) -> #REF! | V54: =H54 -> 1A16_ | W54: =I54 -> 0 | X54: 16 | Y54: =CONCATENATE(J54,"=",K54) -> = | Z54: 0 | AA54: 0 | AB54: Y | AC54: Y | AD54: Y | AE54: Y | AF54: N | AG54: Y | AH54: N | AI54: N
D55: A.5 | E55: 1A17 | F55: A | H55: =CONCATENATE(E55,"_",G55) -> 1A17_ | L55: START | M55: END | T55: 19 | U55: =IF(B55="",U54,B55) -> #REF! | V55: =H55 -> 1A17_ | W55: =I55 -> 0 | X55: 17 | Y55: =CONCATENATE(J55,"=",K55) -> = | Z55: 0 | AA55: 0 | AB55: Y | AC55: Y | AD55: Y | AE55: Y | AF55: N | AG55: Y | AH55: N | AI55: N
D56: A.6 | E56: 1A18 | F56: A | H56: =CONCATENATE(E56,"_",G56) -> 1A18_ | L56: START | M56: END | T56: 20 | U56: =IF(B56="",U55,B56) -> #REF! | V56: =H56 -> 1A18_ | W56: =I56 -> 0 | X56: 18 | Y56: =CONCATENATE(J56,"=",K56) -> = | Z56: 0 | AA56: 0 | AB56: Y | AC56: Y | AD56: Y | AE56: Y | AF56: N | AG56: Y | AH56: N | AI56: N
D57: A.7 | E57: 1A19 | F57: A | H57: =CONCATENATE(E57,"_",G57) -> 1A19_ | L57: START | M57: END | T57: 21 | U57: =IF(B57="",U56,B57) -> #REF! | V57: =H57 -> 1A19_ | W57: =I57 -> 0 | X57: 19 | Y57: =CONCATENATE(J57,"=",K57) -> = | Z57: 0 | AA57: 0 | AB57: Y | AC57: Y | AD57: Y | AE57: Y | AF57: N | AG57: Y | AH57: N | AI57: N
D58: A.8 | E58: 2A10 | F58: A | H58: =CONCATENATE(E58,"_",G58) -> 2A10_ | L58: START | M58: END | T58: 22 | U58: =IF(B58="",U57,B58) -> #REF! | V58: =H58 -> 2A10_ | W58: =I58 -> 0 | X58: 20 | Y58: =CONCATENATE(J58,"=",K58) -> = | Z58: 0 | AA58: 0 | AB58: Y | AC58: Y | AD58: Y | AE58: Y | AF58: N | AG58: Y | AH58: N | AI58: N
D59: A.9 | E59: 2A11 | F59: A | H59: =CONCATENATE(E59,"_",G59) -> 2A11_ | L59: START | M59: END | T59: 23 | U59: =IF(B59="",U58,B59) -> #REF! | V59: =H59 -> 2A11_ | W59: =I59 -> 0 | X59: 21 | Y59: =CONCATENATE(J59,"=",K59) -> = | Z59: 0 | AA59: 0 | AB59: Y | AC59: Y | AD59: Y | AE59: Y | AF59: N | AG59: Y | AH59: N | AI59: N
...

Sheet 3.Action Log 기준정보
B1: ※ 자동검증TOOL(MCC CHECKER) 기준정보 테이블 입력용 | Q1: Samsung Display Confidential
B3: NO | C3: UnitID | D3: Action Name | E3: 설명 | F3: 보기순서 | G3: FROM=TO | H3: 기준MIN | I3: 기준MAX | J3: GlassID Pair오류 | K3: GlassID누락 | L3: HostPPID누락 | M3: EqPPID누락 | N3: LotID누락 | O3: StepID누락 | P3: Pair_Slot구분 | Q3: 기준정보 미포함
A4: ex) | B4: 1 | C4: ='2.Master List 작성(업체 작성 SHEET)'!U44 -> ST01 | D4: ='2.Master List 작성(업체 작성 SHEET)'!V44 -> 1A01_STAGE1_ORIGIN | E4: ='2.Master List 작성(업체 작성 SHEET)'!W44 -> STAGE1 원점 동작 | F4: ='2.Master List 작성(업체 작성 SHEET)'!X44 -> 1 | G4: ='2.Master List 작성(업체 작성 SHEET)'!Y44 -> ST01=ST01 | H4: ='2.Master List 작성(업체 작성 SHEET)'!Z44 -> 0 | I4: ='2.Master List 작성(업체 작성 SHEET)'!AA44 -> 0 | J4: ='2.Master List 작성(업체 작성 SHEET)'!AB44 -> Y | ... Q4: ='2.Master List 작성(업체 작성 SHEET)'!AI44 -> N
B5: 2 | C5: ='2.Master List 작성(업체 작성 SHEET)'!U45 -> ST01 | D5: ='2.Master List 작성(업체 작성 SHEET)'!V45 -> 1A02_ | E5: ='2.Master List 작성(업체 작성 SHEET)'!W45 -> 0 | F5: ='2.Master List 작성(업체 작성 SHEET)'!X45 -> 2 | G5: ='2.Master List 작성(업체 작성 SHEET)'!Y45 -> = | H5: ='2.Master List 작성(업체 작성 SHEET)'!Z45 -> 0 | I5: ='2.Master List 작성(업체 작성 SHEET)'!AA45 -> 0 | J5: ='2.Master List 작성(업체 작성 SHEET)'!AB45 -> Y | ... Q5: ='2.Master List 작성(업체 작성 SHEET)'!AI45 -> N
B6: 3 | C6: ='2.Master List 작성(업체 작성 SHEET)'!#REF! -> #REF! | D6: ='2.Master List 작성(업체 작성 SHEET)'!#REF! -> #REF! | E6: ='2.Master List 작성(업체 작성 SHEET)'!#REF! -> #REF! | F6: ='2.Master List 작성(업체 작성 SHEET)'!#REF! -> #REF! | G6: ='2.Master List 작성(업체 작성 SHEET)'!#REF! -> #REF! | H6: ='2.Master List 작성(업체 작성 SHEET)'!#REF! -> #REF! | I6: ='2.Master List 작성(업체 작성 SHEET)'!#REF! -> #REF! | J6: ='2.Master List 작성(업체 작성 SHEET)'!#REF! -> #REF! | ... Q6: ='2.Master List 작성(업체 작성 SHEET)'!#REF! -> #REF!
B7: 4 | C7: ='2.Master List 작성(업체 작성 SHEET)'!#REF! -> #REF! | D7: ='2.Master List 작성(업체 작성 SHEET)'!#REF! -> #REF! | E7: ='2.Master List 작성(업체 작성 SHEET)'!#REF! -> #REF! | F7: ='2.Master List 작성(업체 작성 SHEET)'!#REF! -> #REF! | G7: ='2.Master List 작성(업체 작성 SHEET)'!#REF! -> #REF! | H7: ='2.Master List 작성(업체 작성 SHEET)'!#REF! -> #REF! | I7: ='2.Master List 작성(업체 작성 SHEET)'!#REF! -> #REF! | J7: ='2.Master List 작성(업체 작성 SHEET)'!#REF! -> #REF! | ... Q7: ='2.Master List 작성(업체 작성 SHEET)'!#REF! -> #REF!
B8: 5 | C8: ='2.Master List 작성(업체 작성 SHEET)'!#REF! -> #REF! | D8: ='2.Master List 작성(업체 작성 SHEET)'!#REF! -> #REF! | E8: ='2.Master List 작성(업체 작성 SHEET)'!#REF! -> #REF! | F8: ='2.Master List 작성(업체 작성 SHEET)'!#REF! -> #REF! | G8: ='2.Master List 작성(업체 작성 SHEET)'!#REF! -> #REF! | H8: ='2.Master List 작성(업체 작성 SHEET)'!#REF! -> #REF! | I8: ='2.Master List 작성(업체 작성 SHEET)'!#REF! -> #REF! | J8: ='2.Master List 작성(업체 작성 SHEET)'!#REF! -> #REF! | ... Q8: ='2.Master List 작성(업체 작성 SHEET)'!#REF! -> #REF!
B9: 6 | C9: ='2.Master List 작성(업체 작성 SHEET)'!#REF! -> #REF! | D9: ='2.Master List 작성(업체 작성 SHEET)'!#REF! -> #REF! | E9: ='2.Master List 작성(업체 작성 SHEET)'!#REF! -> #REF! | F9: ='2.Master List 작성(업체 작성 SHEET)'!#REF! -> #REF! | G9: ='2.Master List 작성(업체 작성 SHEET)'!#REF! -> #REF! | H9: ='2.Master List 작성(업체 작성 SHEET)'!#REF! -> #REF! | I9: ='2.Master List 작성(업체 작성 SHEET)'!#REF! -> #REF! | J9: ='2.Master List 작성(업체 작성 SHEET)'!#REF! -> #REF! | ... Q9: ='2.Master List 작성(업체 작성 SHEET)'!#REF! -> #REF!
B10: 7 | C10: ='2.Master List 작성(업체 작성 SHEET)'!U46 -> #REF! | D10: ='2.Master List 작성(업체 작성 SHEET)'!V46 -> 1A07_CHANGE_PARAMETER | E10: ='2.Master List 작성(업체 작성 SHEET)'!W46 -> STAGE1 동작 Parameter 변경 | F10: ='2.Master List 작성(업체 작성 SHEET)'!X46 -> 7 | G10: ='2.Master List 작성(업체 작성 SHEET)'!Y46 -> ST01=ST01 | H10: ='2.Master List 작성(업체 작성 SHEET)'!Z46 -> 0 | I10: ='2.Master List 작성(업체 작성 SHEET)'!AA46 -> 0 | J10: ='2.Master List 작성(업체 작성 SHEET)'!AB46 -> Y | ... Q10: ='2.Master List 작성(업체 작성 SHEET)'!AI46 -> N
B11: 8 | C11: ='2.Master List 작성(업체 작성 SHEET)'!U47 -> #REF! | D11: ='2.Master List 작성(업체 작성 SHEET)'!V47 -> 1A08_ | E11: ='2.Master List 작성(업체 작성 SHEET)'!W47 -> 0 | F11: ='2.Master List 작성(업체 작성 SHEET)'!X47 -> 8 | G11: ='2.Master List 작성(업체 작성 SHEET)'!Y47 -> = | H11: ='2.Master List 작성(업체 작성 SHEET)'!Z47 -> 0 | I11: ='2.Master List 작성(업체 작성 SHEET)'!AA47 -> 0 | J11: ='2.Master List 작성(업체 작성 SHEET)'!AB47 -> Y | ... Q11: ='2.Master List 작성(업체 작성 SHEET)'!AI47 -> N
B12: 9 | C12: ='2.Master List 작성(업체 작성 SHEET)'!#REF! -> #REF! | D12: ='2.Master List 작성(업체 작성 SHEET)'!#REF! -> #REF! | E12: ='2.Master List 작성(업체 작성 SHEET)'!#REF! -> #REF! | F12: ='2.Master List 작성(업체 작성 SHEET)'!#REF! -> #REF! | G12: ='2.Master List 작성(업체 작성 SHEET)'!#REF! -> #REF! | H12: ='2.Master List 작성(업체 작성 SHEET)'!#REF! -> #REF! | I12: ='2.Master List 작성(업체 작성 SHEET)'!#REF! -> #REF! | J12: ='2.Master List 작성(업체 작성 SHEET)'!#REF! -> #REF! | ... Q12: ='2.Master List 작성(업체 작성 SHEET)'!#REF! -> #REF!
B13: 10 | C13: ='2.Master List 작성(업체 작성 SHEET)'!U48 -> #REF! | D13: ='2.Master List 작성(업체 작성 SHEET)'!V48 -> 1A10_WAIT_COMPONENT_IN | E13: ='2.Master List 작성(업체 작성 SHEET)'!W48 -> 자재 투입 대기 | F13: ='2.Master List 작성(업체 작성 SHEET)'!X48 -> 10 | G13: ='2.Master List 작성(업체 작성 SHEET)'!Y48 -> ST01=ST01 | H13: ='2.Master List 작성(업체 작성 SHEET)'!Z48 -> 0 | I13: ='2.Master List 작성(업체 작성 SHEET)'!AA48 -> 0 | J13: ='2.Master List 작성(업체 작성 SHEET)'!AB48 -> Y | ... Q13: ='2.Master List 작성(업체 작성 SHEET)'!AI48 -> N
B14: 11 | C14: ='2.Master List 작성(업체 작성 SHEET)'!U49 -> #REF! | D14: ='2.Master List 작성(업체 작성 SHEET)'!V49 -> 1A11_COMPONENT_IN | E14: ='2.Master List 작성(업체 작성 SHEET)'!W49 -> 자재 투입 | F14: ='2.Master List 작성(업체 작성 SHEET)'!X49 -> 11 | G14: ='2.Master List 작성(업체 작성 SHEET)'!Y49 -> ST01=ST01 | H14: ='2.Master List 작성(업체 작성 SHEET)'!Z49 -> 0 | I14: ='2.Master List 작성(업체 작성 SHEET)'!AA49 -> 0 | J14: ='2.Master List 작성(업체 작성 SHEET)'!AB49 -> Y | ... Q14: ='2.Master List 작성(업체 작성 SHEET)'!AI49 -> N
B15: 12 | C15: ='2.Master List 작성(업체 작성 SHEET)'!U50 -> #REF! | D15: ='2.Master List 작성(업체 작성 SHEET)'!V50 -> 1A12_INSPECTION | E15: ='2.Master List 작성(업체 작성 SHEET)'!W50 -> 검사 | F15: ='2.Master List 작성(업체 작성 SHEET)'!X50 -> 12 | G15: ='2.Master List 작성(업체 작성 SHEET)'!Y50 -> ST01=ST01 | H15: ='2.Master List 작성(업체 작성 SHEET)'!Z50 -> 0 | I15: ='2.Master List 작성(업체 작성 SHEET)'!AA50 -> 0 | J15: ='2.Master List 작성(업체 작성 SHEET)'!AB50 -> Y | ... Q15: ='2.Master List 작성(업체 작성 SHEET)'!AI50 -> N
B16: 13 | C16: ='2.Master List 작성(업체 작성 SHEET)'!U51 -> #REF! | D16: ='2.Master List 작성(업체 작성 SHEET)'!V51 -> 1A13_WAIT_COMPONENT_OUT | E16: ='2.Master List 작성(업체 작성 SHEET)'!W51 -> 자재 배출 대기 | F16: ='2.Master List 작성(업체 작성 SHEET)'!X51 -> 13 | G16: ='2.Master List 작성(업체 작성 SHEET)'!Y51 -> ST01=ST01 | H16: ='2.Master List 작성(업체 작성 SHEET)'!Z51 -> 0 | I16: ='2.Master List 작성(업체 작성 SHEET)'!AA51 -> 0 | J16: ='2.Master List 작성(업체 작성 SHEET)'!AB51 -> Y | ... Q16: ='2.Master List 작성(업체 작성 SHEET)'!AI51 -> N
B17: 14 | C17: ='2.Master List 작성(업체 작성 SHEET)'!U52 -> #REF! | D17: ='2.Master List 작성(업체 작성 SHEET)'!V52 -> 1A14_ | E17: ='2.Master List 작성(업체 작성 SHEET)'!W52 -> 0 | F17: ='2.Master List 작성(업체 작성 SHEET)'!X52 -> 14 | G17: ='2.Master List 작성(업체 작성 SHEET)'!Y52 -> = | H17: ='2.Master List 작성(업체 작성 SHEET)'!Z52 -> 0 | I17: ='2.Master List 작성(업체 작성 SHEET)'!AA52 -> 0 | J17: ='2.Master List 작성(업체 작성 SHEET)'!AB52 -> Y | ... Q17: ='2.Master List 작성(업체 작성 SHEET)'!AI52 -> N
B18: 15 | C18: ='2.Master List 작성(업체 작성 SHEET)'!U53 -> #REF! | D18: ='2.Master List 작성(업체 작성 SHEET)'!V53 -> 1A15_ | E18: ='2.Master List 작성(업체 작성 SHEET)'!W53 -> 0 | F18: ='2.Master List 작성(업체 작성 SHEET)'!X53 -> 15 | G18: ='2.Master List 작성(업체 작성 SHEET)'!Y53 -> = | H18: ='2.Master List 작성(업체 작성 SHEET)'!Z53 -> 0 | I18: ='2.Master List 작성(업체 작성 SHEET)'!AA53 -> 0 | J18: ='2.Master List 작성(업체 작성 SHEET)'!AB53 -> Y | ... Q18: ='2.Master List 작성(업체 작성 SHEET)'!AI53 -> N
B19: 16 | C19: ='2.Master List 작성(업체 작성 SHEET)'!U54 -> #REF! | D19: ='2.Master List 작성(업체 작성 SHEET)'!V54 -> 1A16_ | E19: ='2.Master List 작성(업체 작성 SHEET)'!W54 -> 0 | F19: ='2.Master List 작성(업체 작성 SHEET)'!X54 -> 16 | G19: ='2.Master List 작성(업체 작성 SHEET)'!Y54 -> = | H19: ='2.Master List 작성(업체 작성 SHEET)'!Z54 -> 0 | I19: ='2.Master List 작성(업체 작성 SHEET)'!AA54 -> 0 | J19: ='2.Master List 작성(업체 작성 SHEET)'!AB54 -> Y | ... Q19: ='2.Master List 작성(업체 작성 SHEET)'!AI54 -> N
B20: 17 | C20: ='2.Master List 작성(업체 작성 SHEET)'!U55 -> #REF! | D20: ='2.Master List 작성(업체 작성 SHEET)'!V55 -> 1A17_ | E20: ='2.Master List 작성(업체 작성 SHEET)'!W55 -> 0 | F20: ='2.Master List 작성(업체 작성 SHEET)'!X55 -> 17 | G20: ='2.Master List 작성(업체 작성 SHEET)'!Y55 -> = | H20: ='2.Master List 작성(업체 작성 SHEET)'!Z55 -> 0 | I20: ='2.Master List 작성(업체 작성 SHEET)'!AA55 -> 0 | J20: ='2.Master List 작성(업체 작성 SHEET)'!AB55 -> Y | ... Q20: ='2.Master List 작성(업체 작성 SHEET)'!AI55 -> N
B21: 18 | C21: ='2.Master List 작성(업체 작성 SHEET)'!U56 -> #REF! | D21: ='2.Master List 작성(업체 작성 SHEET)'!V56 -> 1A18_ | E21: ='2.Master List 작성(업체 작성 SHEET)'!W56 -> 0 | F21: ='2.Master List 작성(업체 작성 SHEET)'!X56 -> 18 | G21: ='2.Master List 작성(업체 작성 SHEET)'!Y56 -> = | H21: ='2.Master List 작성(업체 작성 SHEET)'!Z56 -> 0 | I21: ='2.Master List 작성(업체 작성 SHEET)'!AA56 -> 0 | J21: ='2.Master List 작성(업체 작성 SHEET)'!AB56 -> Y | ... Q21: ='2.Master List 작성(업체 작성 SHEET)'!AI56 -> N
B22: 19 | C22: ='2.Master List 작성(업체 작성 SHEET)'!U57 -> #REF! | D22: ='2.Master List 작성(업체 작성 SHEET)'!V57 -> 1A19_ | E22: ='2.Master List 작성(업체 작성 SHEET)'!W57 -> 0 | F22: ='2.Master List 작성(업체 작성 SHEET)'!X57 -> 19 | G22: ='2.Master List 작성(업체 작성 SHEET)'!Y57 -> = | H22: ='2.Master List 작성(업체 작성 SHEET)'!Z57 -> 0 | I22: ='2.Master List 작성(업체 작성 SHEET)'!AA57 -> 0 | J22: ='2.Master List 작성(업체 작성 SHEET)'!AB57 -> Y | ... Q22: ='2.Master List 작성(업체 작성 SHEET)'!AI57 -> N
B23: 20 | C23: ='2.Master List 작성(업체 작성 SHEET)'!U58 -> #REF! | D23: ='2.Master List 작성(업체 작성 SHEET)'!V58 -> 2A10_ | E23: ='2.Master List 작성(업체 작성 SHEET)'!W58 -> 0 | F23: ='2.Master List 작성(업체 작성 SHEET)'!X58 -> 20 | G23: ='2.Master List 작성(업체 작성 SHEET)'!Y58 -> = | H23: ='2.Master List 작성(업체 작성 SHEET)'!Z58 -> 0 | I23: ='2.Master List 작성(업체 작성 SHEET)'!AA58 -> 0 | J23: ='2.Master List 작성(업체 작성 SHEET)'!AB58 -> Y | ... Q23: ='2.Master List 작성(업체 작성 SHEET)'!AI58 -> N
B24: 21 | C24: ='2.Master List 작성(업체 작성 SHEET)'!U59 -> #REF! | D24: ='2.Master List 작성(업체 작성 SHEET)'!V59 -> 2A11_ | E24: ='2.Master List 작성(업체 작성 SHEET)'!W59 -> 0 | F24: ='2.Master List 작성(업체 작성 SHEET)'!X59 -> 21 | G24: ='2.Master List 작성(업체 작성 SHEET)'!Y59 -> = | H24: ='2.Master List 작성(업체 작성 SHEET)'!Z59 -> 0 | I24: ='2.Master List 작성(업체 작성 SHEET)'!AA59 -> 0 | J24: ='2.Master List 작성(업체 작성 SHEET)'!AB59 -> Y | ... Q24: ='2.Master List 작성(업체 작성 SHEET)'!AI59 -> N
... B38: 35 | C38: ='2.Master List 작성(업체 작성 SHEET)'!U73 -> ST02 | D38: ='2.Master List 작성(업체 작성 SHEET)'!V73 -> 1B17_ | E38: ='2.Master List 작성(업체 작성 SHEET)'!W73 -> 0 | F38: ='2.Master List 작성(업체 작성 SHEET)'!X73 -> 35 | G38: ='2.Master List 작성(업체 작성 SHEET)'!Y73 -> ST02=ST02 | H38: ='2.Master List 작성(업체 작성 SHEET)'!Z73 -> 0 | I38: ='2.Master List 작성(업체 작성 SHEET)'!AA73 -> 0 | J38: ='2.Master List 작성(업체 작성 SHEET)'!AB73 -> Y | ... Q38: ='2.Master List 작성(업체 작성 SHEET)'!AI73 -> N
B39: 36 | C39: ='2.Master List 작성(업체 작성 SHEET)'!U80 -> ST02 | D39: ='2.Master List 작성(업체 작성 SHEET)'!V80 -> 1B24_ | E39: ='2.Master List 작성(업체 작성 SHEET)'!W80 -> 0 | F39: ='2.Master List 작성(업체 작성 SHEET)'!X80 -> 36 | G39: ='2.Master List 작성(업체 작성 SHEET)'!Y80 -> = | H39: ='2.Master List 작성(업체 작성 SHEET)'!Z80 -> 0 | I39: ='2.Master List 작성(업체 작성 SHEET)'!AA80 -> 0 | J39: ='2.Master List 작성(업체 작성 SHEET)'!AB80 -> Y | ... Q39: ='2.Master List 작성(업체 작성 SHEET)'!AI80 -> N
B40: 37 | C40: ='2.Master List 작성(업체 작성 SHEET)'!U81 -> ST02 | D40: ='2.Master List 작성(업체 작성 SHEET)'!V81 -> 1B25_ | E40: ='2.Master List 작성(업체 작성 SHEET)'!W81 -> 0 | F40: ='2.Master List 작성(업체 작성 SHEET)'!X81 -> 37 | G40: ='2.Master List 작성(업체 작성 SHEET)'!Y81 -> = | H40: ='2.Master List 작성(업체 작성 SHEET)'!Z81 -> 0 | I40: ='2.Master List 작성(업체 작성 SHEET)'!AA81 -> 0 | J40: ='2.Master List 작성(업체 작성 SHEET)'!AB81 -> Y | ... Q40: ='2.Master List 작성(업체 작성 SHEET)'!AI81 -> N
B41: 38 | C41: ='2.Master List 작성(업체 작성 SHEET)'!U82 -> ST02 | D41: ='2.Master List 작성(업체 작성 SHEET)'!V82 -> 1B20_ | E41: ='2.Master List 작성(업체 작성 SHEET)'!W82 -> 0 | F41: ='2.Master List 작성(업체 작성 SHEET)'!X82 -> 38 | G41: ='2.Master List 작성(업체 작성 SHEET)'!Y82 -> = | H41: ='2.Master List 작성(업체 작성 SHEET)'!Z82 -> 0 | I41: ='2.Master List 작성(업체 작성 SHEET)'!AA82 -> 0 | J41: ='2.Master List 작성(업체 작성 SHEET)'!AB82 -> Y | ... Q41: ='2.Master List 작성(업체 작성 SHEET)'!AI82 -> N
B42: 39 | C42: ='2.Master List 작성(업체 작성 SHEET)'!U83 -> SH01 | D42: ='2.Master List 작성(업체 작성 SHEET)'!V83 -> 1C01_HEAD X_ORIGIN | E42: ='2.Master List 작성(업체 작성 SHEET)'!W83 -> HEAD X축 원점 | F42: ='2.Master List 작성(업체 작성 SHEET)'!X83 -> 39 | G42: ='2.Master List 작성(업체 작성 SHEET)'!Y83 -> SH01=SH01 | H42: ='2.Master List 작성(업체 작성 SHEET)'!Z83 -> 0 | I42: ='2.Master List 작성(업체 작성 SHEET)'!AA83 -> 0 | J42: ='2.Master List 작성(업체 작성 SHEET)'!AB83 -> Y | ... Q42: ='2.Master List 작성(업체 작성 SHEET)'!AI83 -> N
B43: 40 | C43: ='2.Master List 작성(업체 작성 SHEET)'!U84 -> SH01 | D43: ='2.Master List 작성(업체 작성 SHEET)'!V84 -> 1C02_HEAD_T_ORIGN | E43: ='2.Master List 작성(업체 작성 SHEET)'!W84 -> HEAD T축 원점 | F43: ='2.Master List 작성(업체 작성 SHEET)'!X84 -> 40 | G43: ='2.Master List 작성(업체 작성 SHEET)'!Y84 -> SH01=SH01 | H43: ='2.Master List 작성(업체 작성 SHEET)'!Z84 -> 0 | I43: ='2.Master List 작성(업체 작성 SHEET)'!AA84 -> 0 | J43: ='2.Master List 작성(업체 작성 SHEET)'!AB84 -> Y | ... Q43: ='2.Master List 작성(업체 작성 SHEET)'!AI84 -> N
B44: 41 | C44: ='2.Master List 작성(업체 작성 SHEET)'!U85 -> SH01 | D44: ='2.Master List 작성(업체 작성 SHEET)'!V85 -> 1C03_ | E44: ='2.Master List 작성(업체 작성 SHEET)'!W85 -> 0 | F44: ='2.Master List 작성(업체 작성 SHEET)'!X85 -> 41 | G44: ='2.Master List 작성(업체 작성 SHEET)'!Y85 -> = | H44: ='2.Master List 작성(업체 작성 SHEET)'!Z85 -> 0 | I44: ='2.Master List 작성(업체 작성 SHEET)'!AA85 -> 0 | J44: ='2.Master List 작성(업체 작성 SHEET)'!AB85 -> Y | ... Q44: ='2.Master List 작성(업체 작성 SHEET)'!AI85 -> N
B45: 42 | C45: ='2.Master List 작성(업체 작성 SHEET)'!U86 -> SH01 | D45: ='2.Master List 작성(업체 작성 SHEET)'!V86 -> 1C04_CHANGE_PARAMETER | E45: ='2.Master List 작성(업체 작성 SHEET)'!W86 -> HEAD 동작 Parameter 변경 | F45: ='2.Master List 작성(업체 작성 SHEET)'!X86 -> 42 | G45: ='2.Master List 작성(업체 작성 SHEET)'!Y86 -> SH01=SH01 | H45: ='2.Master List 작성(업체 작성 SHEET)'!Z86 -> 0 | I45: ='2.Master List 작성(업체 작성 SHEET)'!AA86 -> 0 | J45: ='2.Master List 작성(업체 작성 SHEET)'!AB86 -> Y | ... Q45: ='2.Master List 작성(업체 작성 SHEET)'!AI86 -> N
B46: 43 | C46: ='2.Master List 작성(업체 작성 SHEET)'!U87 -> SH01 | D46: ='2.Master List 작성(업체 작성 SHEET)'!V87 -> 1C05_ | E46: ='2.Master List 작성(업체 작성 SHEET)'!W87 -> 0 | F46: ='2.Master List 작성(업체 작성 SHEET)'!X87 -> 43 | G46: ='2.Master List 작성(업체 작성 SHEET)'!Y87 -> = | H46: ='2.Master List 작성(업체 작성 SHEET)'!Z87 -> 0 | I46: ='2.Master List 작성(업체 작성 SHEET)'!AA87 -> 0 | J46: ='2.Master List 작성(업체 작성 SHEET)'!AB87 -> Y | ... Q46: ='2.Master List 작성(업체 작성 SHEET)'!AI87 -> N
B47: 44 | C47: ='2.Master List 작성(업체 작성 SHEET)'!U88 -> SH01 | D47: ='2.Master List 작성(업체 작성 SHEET)'!V88 -> 1C06_ | E47: ='2.Master List 작성(업체 작성 SHEET)'!W88 -> 0 | F47: ='2.Master List 작성(업체 작성 SHEET)'!X88 -> 44 | G47: ='2.Master List 작성(업체 작성 SHEET)'!Y88 -> = | H47: ='2.Master List 작성(업체 작성 SHEET)'!Z88 -> 0 | I47: ='2.Master List 작성(업체 작성 SHEET)'!AA88 -> 0 | J47: ='2.Master List 작성(업체 작성 SHEET)'!AB88 -> Y | ... Q47: ='2.Master List 작성(업체 작성 SHEET)'!AI88 -> N
B48: 45 | C48: ='2.Master List 작성(업체 작성 SHEET)'!U89 -> SH01 | D48: ='2.Master List 작성(업체 작성 SHEET)'!V89 -> 1C10_INSPECTION | E48: ='2.Master List 작성(업체 작성 SHEET)'!W89 -> 검사 | F48: ='2.Master List 작성(업체 작성 SHEET)'!X89 -> 45 | G48: ='2.Master List 작성(업체 작성 SHEET)'!Y89 -> SH01=SH01 | H48: ='2.Master List 작성(업체 작성 SHEET)'!Z89 -> 0 | I48: ='2.Master List 작성(업체 작성 SHEET)'!AA89 -> 0 | J48: ='2.Master List 작성(업체 작성 SHEET)'!AB89 -> Y | ... Q48: ='2.Master List 작성(업체 작성 SHEET)'!AI89 -> N
B49: 46 | C49: ='2.Master List 작성(업체 작성 SHEET)'!U90 -> SH01 | D49: ='2.Master List 작성(업체 작성 SHEET)'!V90 -> 1C11_ | E49: ='2.Master List 작성(업체 작성 SHEET)'!W90 -> 0 | F49: ='2.Master List 작성(업체 작성 SHEET)'!X90 -> 46 | G49: ='2.Master List 작성(업체 작성 SHEET)'!Y90 -> SH01=SH01 | H49: ='2.Master List 작성(업체 작성 SHEET)'!Z90 -> 0 | I49: ='2.Master List 작성(업체 작성 SHEET)'!AA90 -> 0 | J49: ='2.Master List 작성(업체 작성 SHEET)'!AB90 -> Y | ... Q49: ='2.Master List 작성(업체 작성 SHEET)'!AI90 -> N
B50: 47 | C50: ='2.Master List 작성(업체 작성 SHEET)'!U91 -> SH01 | D50: ='2.Master List 작성(업체 작성 SHEET)'!V91 -> 1C12_ | E50: ='2.Master List 작성(업체 작성 SHEET)'!W91 -> 0 | F50: ='2.Master List 작성(업체 작성 SHEET)'!X91 -> 47 | G50: ='2.Master List 작성(업체 작성 SHEET)'!Y91 -> SH01=SH01 | H50: ='2.Master List 작성(업체 작성 SHEET)'!Z91 -> 0 | I50: ='2.Master List 작성(업체 작성 SHEET)'!AA91 -> 0 | J50: ='2.Master List 작성(업체 작성 SHEET)'!AB91 -> Y | ... Q50: ='2.Master List 작성(업체 작성 SHEET)'!AI91 -> N
... B287: 284 | C287: ='2.Master List 작성(업체 작성 SHEET)'!U328 -> 0 | D287: ='2.Master List 작성(업체 작성 SHEET)'!V328 -> 0 | E287: ='2.Master List 작성(업체 작성 SHEET)'!W328 -> 0 | F287: ='2.Master List 작성(업체 작성 SHEET)'!X328 -> 0 | G287: ='2.Master List 작성(업체 작성 SHEET)'!Y328 -> 0 | H287: ='2.Master List 작성(업체 작성 SHEET)'!Z328 -> 0 | I287: ='2.Master List 작성(업체 작성 SHEET)'!AA328 -> 0 | J287: ='2.Master List 작성(업체 작성 SHEET)'!AB328 -> 0 | ... Q287: ='2.Master List 작성(업체 작성 SHEET)'!AI328 -> 0
B288: 285 | H288: 0 | I288: 0 | J288: Y | K288: Y | L288: Y | M288: Y | N288: Y | O288: Y | P288: N | Q288: N
B289: 286 | H289: 0 | I289: 0 | J289: Y | K289: Y | L289: Y | M289: Y | N289: Y | O289: Y | P289: N | Q289: N
B290: 287 | H290: 0 | I290: 0 | J290: Y | K290: Y | L290: Y | M290: Y | N290: Y | O290: Y | P290: N | Q290: N
...

Sheet MasterList 작성 방법 예시(참조 양식)
P1: Samsung Display Confidential
B2: Maker 명 | C2: 작성 必 | F2: MCC 담당자/직함 (Maker) | G2: 작성 必 | H2: 작성일 | I2: SDC 기술부서 MCC담당자 | J2: 작성 必 | L2: SDC 중소형 MOD 제조혁신 MCC 담당자
B3: 설비 명 | C3: 작성 必 | F3: 연락처 | G3: 작성 必 | H3: 작성 必 | I3: SDC 기술부서 MCC 확인 | J3: OK / NG | L3: SDC 중소형 MOD 제조혁신 MCC 담당자 | O3: OK / NG
B5: ※ 설비 입고전 협의된 일정內에 MCC Master List를 작성 제출해야하며, 입고후 Maker에서는 매주 정합성 자체검증하여 근거자료(MCC Log)와 함께 제출한다.
B6: 1. Modeling
B7: MCC의 모델링은 자재 이동단위로 상세하게 나눈다. - CIM Modeling보다 세분화 시킴
B8: EQP ID | C8: Layer01 | D8: Layer02 | E8: Layer03 | F8: Layer04 | G8: Description
B9: 설비 EQP ID 확정 후 | C9: 설비 EQP ID 확정 후 | D9: LR01 | E9: xxx | F9: xxx | G9: LOADER ROBOT
D10: ST01 | E10: xxx | F10: xxx | G10: STAGE TRANSFER
D11: FT01 | E11: xxx | F11: xxx | G11: FORK TYPE TRANSFER
D12: PS10 | E12: xxx | F12: xxx | G12: PROCESS STAGE1
D13: PS20 | E13: xxx | F13: xxx | G13: PROCESS STAGE2
B15: 2. Layout
B16: 하기 Sample처럼 ModuleID, 구성부품NAME, PANEL 및 자재 이동방향을 표현한다. ( UNIT명 기준은 1.Modeling 에 최종 Layer명으로 작성 )
AR33: LR01
AR34: NO | AS34: PARTS NAME
AR35: 1 | AS35: ROBOT(ONE HAND)
B36: 3. Moving Path | AR36: 2 | AS36: UP/DOWN CYLINDER
B37: 자동운전時 Panel 및 Panel을 포함한 모든자재의 이동경로의 CASE를 나열한다.
B38: CASE | C38: 자재명 | D38: PATH | AR38: ST01
B39: 1 | C39: CELL | D39: LR01 → ST01 → FT01 → PS11, PS12 | AR39: NO | AS39: PARTS NAME
B40: 2 | C40: CELL | AR40: 1 | AS40: VISION CAMERA
B41: 3 | C41: CELL | AR41: 2 | AS41: USC
B42: 4 | C42: CELL | AR42: 3 | AS42: PLASMA
B43: 5 | C43: FPC | AR43: 4 | AS43: LINEAR MOTOR(X-AXIS)
B44: 7 | C44: TRAY
AR45: FT01
B46: 동일한 Unit의 경로가 나누어져 있는 경우는 ' , '를 사용하여 경우의 수를 표현 해도 무방하다. | AR46: NO | AS46: PARTS NAME
B47: 예시) 동일한 동작의 Unit이 나누어져 있을때 | AR47: 1 | AS47: UP/DOWN CYLINDER
B48: TR01 → ST11,ST12,ST13 → TR02 → ST21,ST22 → TR03
AR49: PS11
AR50: NO | AS50: PARTS NAME
AR51: 1 | AS51: SERVO MOTOR
AR53: PS12
AR54: NO | AS54: PARTS NAME
B55: 4. Action Log Area | AR55: 1 | AS55: SERVO MOTOR
B57: Initial : 설비전원 인가후 서버원점수행등의 초기준비 동작
B58: Change : Recipe Change 또는 Tool Cleaning, Align등의 간헐적 Job준비동작
B59: Cycle : 작업물(Glass) 로딩을 시작으로 하여 작업물 처리(기구물 이동&가공 및 화학처리 모든 작업포함), 작업물 언로딩준비완료, 작업물 언로딩 실행, 다음 작업물 로딩준비완료까지의 연속Cycle동작
B60: Single : CYCLE동작 외 번외적으로 발생되는 단독적인 동작에 대해 기재
...

Sheet 동작 시점 정의 (참조 양식)
AF2: Samsung Display Confidential
B3: ◆ 각 Step 정의
B5: COMPONENT IN | E5: 자재가 상류 Unit에서 해당 Unit으로 Load 되는 상태
B6: OUT_WAIT_TIME | E6: 투입 Unit 동작 완료후 배출 Unit 투입전까지 대기시간
B7: COMPONENT OUT | E7: 자재가 해당 Unit에서 하류 Unit으로 Unload 되는 상태
B8: IN_WAIT_TIME | E8: 배출 Unit 동작 완료후 투입 Unit 투입전까지 대기시간
B11: ◆ COMPONENT_IN, COMPONENT_OUT 시점 정의
B13: 1. 일반적 TRANSFER (UP/DOWN 구분 동작 CASE)
B14: COMPONENT IN
B15: TRANSFER COMPONENT_IN START 시점 = TRANSFER CELL 받는 DOWN START 시점 (STAGE Z축 이동 시 Z축 UP START 시점) | R15: TRANSFER COMPONENT_IN END 시점 = TRANSFER CELL 받는 UP START 시점 (STAGE Z축 이동 시 Z축 DOWN START 시점)
B34: STAGE COMPONENT_OUT START 시점 = TRANSFER CELL 받는 DOWN START 시점과 동일 | R34: STAGE COMPONENT_OUT END 시점 = TRANSFER CELL 받는 UP START 시점과 동일
B37: COMPONENT OUT
B38: TRANSFER COMPONENT_OUT START 시점 = TRANSFER CELL 주는 DOWN START 시점 (STAGE Z축 이동 시 Z축 UP START 시점) | R38: TRANSFER COMPONENT_OUT END 시점 = TRANSFER CELL 주는 UP START 시점 (STAGE Z축 이동 시 Z축 DOWN START 시점)
B55: STAGE COMPONENT_IN START 시점 = TRANSFER CELL 주는 DOWN START 시점과 동일 | R55: STAGE COMPONENT_IN END 시점 = TRANSFER CELL 받는 UP START 시점과 동일
C58: UNIT | D58: NAME | F58: … | G58: FROM | H58: TO
C59: PS01 | D59: COMPONENT OUT | F59: … | G59: PS01 | H59: TR01
D60: PUT_VAC_OFF | F60: … | G60: PS01 | H60: TR01
C61: TR01 | D61: COMPONENT_IN | F61: … | G61: PS01 | H61: TR01
D62: GET_CYL_DOWN | F62: … | G62: PS01 | H62: TR01
D63: GET_VAC_ON | F63: … | G63: PS01 | H63: TR01
D64: GET_CYL_UP | F64: … | G64: PS01 | H64: TR01
D65: MOVE_Y_ULD_POS | G65: TR01 | H65: TR01
D66: COMPONENT_OUT | F66: … | G66: TR01 | H66: PS02
D67: PUT_CYL_DOWN | F67: … | G67: TR01 | H67: PS02
D68: PUT_VAC_OFF | F68: … | G68: TR01 | H68: PS02
D69: PUT_CYL_UP | F69: … | G69: TR01 | H69: PS02
D70: MOVE_Y_LD_POS | G70: TR01 | H70: TR01
C71: PS02 | D71: COMPONENT IN | F71: … | G71: TR01 | H71: PS02
D72: GET_VAC_ON | F72: … | G72: TR01 | H72: PS02
B77: ◆ INITIAL STEP 시점 정의
C79: UNIT INITIAL START 시점 = 설비 작화 "READY" START 시점
C80: UNIT INITIAL END 시점 = 설비 작화 "READY" END(완료) 시점
C81: ※ 전체 초기화 시 각 UNIT별 READY 신호 사용하여 표시
B108: ◆ VISION STEP 정의
C109: VISION을 활용한 (VISION + 프로그램) 작업에 적용
C110: VISION_ALIGN, VISION_INSPECT 등) START 시점 = VISION_GRAB, VISION_SCAN, MARK_SERCH 시작 시점
C111: VISION_ALIGN, VISION_INSPECT 등) END 시점 = VISION_GRAB, VISION_SCAN, MARK_SERCH, 보정 완료 시점
C112: (목적을 가진 특수 검사의 경우 GRAB과 INPECT을 구분 = 계측기를 통한 연산, VISION을 통한 양/불판정 연산 등)
C113: 여러 항목을 검사하는 경우 검사항목 구분 (TRAY CELL 적재 유/무 검사, TRAY CELL 올라탐 검사 각각 구분)
B118: ◆ VISION/MCR/BCR TRY COUNT STEP 정의
...
