Workbook

Sheet Scenario Check Summary
B1: 대외비 2020.07.13/송지훈 프로/모듈IT그룹
H2: 대외비
B3: Control Scenario Check List Summary
D5: Use | E5: 출하 검수 | G5: Line Test
E6: Total | G6: Total
E7: OK | F7: Rate | G7: OK | H7: Rate
D8: =SUM(D16,D19,D25,D29,D32,D36,D39,D46,D53,D57,D60,D64,D73,D81) -> 105 | E8: =SUM(E16,E19,E25,E29,E32,E36,E39,E46,E53,E57,E60,E64,E73,E81) -> 102 | F8: =IF(D8<>0, E8/D8, 1) -> 0.97142857 | G8: =SUM(G16,G19,G25,G29,G32,G36,G39,G46,G53,G57,G60,G64,G73,G81) -> 0 | H8: =IF(D8<>0, G8/D8, 1) -> 0
B10: Category | C10: Item | D10: Use | G10: Line Test
E11: Total | G11: Total
E12: OK | F12: Rate | G12: OK | H12: Rate
B13: 1. Connection | C13: 1.1 Host - EQ Connection | D13: =Connection!H12 -> 1 | E13: =Connection!I12 -> 1 | F13: =IF(D13<>0, E13/D13, "-") -> 1 | G13: =Connection!J12 -> 0 | H13: =IF(D13<>0, G13/D13, "-") -> 0
C14: 1.2 Link Test & Fail Over | D14: =Connection!H85 -> 1 | E14: =Connection!I85 -> 1 | F14: =IF(D14<>0, E14/D14, "-") -> 1 | G14: =Connection!J85 -> 0 | H14: =IF(D14<>0, G14/D14, "-") -> 0
C15: 1.3 Communication Error | D15: =Connection!H146 -> 1 | E15: =Connection!I146 -> 1 | F15: =IF(D15<>0, E15/D15, "-") -> 1 | G15: =Connection!J146 -> 0 | H15: =IF(D15<>0, G15/D15, "-") -> 0
C16: Connection Sub Total | D16: =SUM(D13:D15) -> 3 | E16: =SUM(E13:E15) -> 3 | F16: =IF(D16<>0, E16/D16, "-") -> 1 | G16: =SUM(G13:G15) -> 0 | H16: =IF(D16<>0, G16/D16, "-") -> 0
B17: 2. Initializing | C17: 2.1 Initial Communication | D17: =Initial!H26 -> 2 | E17: =Initial!I26 -> 2 | F17: =IF(D17<>0, E17/D17, "-") -> 1 | G17: =Initial!J26 -> 0 | H17: =IF(D17<>0, G17/D17, "-") -> 0
C18: 2.2 Equipment Current State Check | D18: =Initial!H56 -> 6 | E18: =Initial!I56 -> 6 | F18: =IF(D18<>0, E18/D18, "-") -> 1 | G18: =Initial!J56 -> 0 | H18: =IF(D18<>0, G18/D18, "-") -> 0
C19: Initial & Current State Check Sub Total | D19: =SUM(D17:D18) -> 8 | E19: =SUM(E17:E18) -> 8 | F19: =IF(D19<>0, E19/D19, "-") -> 1 | G19: =SUM(G17:G18) -> 0 | H19: =IF(D19<>0, G19/D19, "-") -> 0
B20: 3. RMS | C20: 3.1 PPID List & Recipe Body Check | D20: =RMS!H34 -> 4 | E20: =RMS!I34 -> 4 | F20: =IF(D20<>0, E20/D20, "-") -> 1 | G20: =RMS!J34 -> 0 | H20: =IF(D20<>0, G20/D20, "-") -> 0
C21: 3.2 Recipe Body Control By Engineer | D21: =RMS!H96 -> 4 | E21: =RMS!I96 -> 4 | F21: =IF(D21<>0, E21/D21, "-") -> 1 | G21: =RMS!J96 -> 0 | H21: =IF(D21<>0, G21/D21, "-") -> 0
C22: 3.3 Current Running PPID Check | D22: =RMS!H162 -> 2 | E22: =RMS!I162 -> 2 | F22: =IF(D22<>0, E22/D22, "-") -> 1 | G22: =RMS!J162 -> 0 | H22: =IF(D22<>0, G22/D22, "-") -> 0
C23: 3.4 PPID Change Report (Job Change) | D23: =RMS!H190 -> 1 | E23: =RMS!I190 -> 1 | F23: =IF(D23<>0, E23/D23, "-") -> 1 | G23: =RMS!J190 -> 0 | H23: =IF(D23<>0, G23/D23, "-") -> 0
C24: 3.5 Recipe Contents Change by Host - CREATE/DELETE/MODIFY | D24: =RMS!H209 -> 10 | E24: =RMS!I209 -> 10 | F24: =IF(D24<>0, E24/D24, "-") -> 1 | G24: =RMS!J209 -> 0 | H24: =IF(D24<>0, G24/D24, "-") -> 0
C25: RMS Sub Total | D25: =SUM(D20:D24) -> 21 | E25: =SUM(E20:E24) -> 21 | F25: =IF(D25<>0, E25/D25, "-") -> 1 | G25: =SUM(G20:G24) -> 0 | H25: =IF(D25<>0, G25/D25, "-") -> 0
B26: 4. ECM | C26: 4.1 ECID List Check | D26: =ECM!H28 -> 4 | E26: =ECM!I28 -> 4 | F26: =IF(D26<>0, E26/D26, "-") -> 1 | G26: =ECM!J28 -> 0 | H26: =IF(D26<>0, G26/D26, "-") -> 0
C27: 4.2 ECID Change by Eqp (NAK) | D27: =ECM!H90 -> 1 | E27: =ECM!I90 -> 1 | F27: =IF(D27<>0, E27/D27, "-") -> 1 | G27: =ECM!J90 -> 0 | H27: =IF(D27<>0, G27/D27, "-") -> 0
C28: 4.3 ECID Change by Host (NAK) | D28: =ECM!H128 -> 0 | E28: =ECM!I128 -> 0 | F28: =IF(D28<>0, E28/D28, "-") -> - | G28: =ECM!J128 -> 0 | H28: =IF(D28<>0, G28/D28, "-") -> -
C29: ECM Sub Total | D29: =SUM(D26:D28) -> 5 | E29: =SUM(E26:E28) -> 5 | F29: =IF(D29<>0, E29/D29, "-") -> 1 | G29: =SUM(G26:G28) -> 0 | H29: =IF(D29<>0, G29/D29, "-") -> 0
B30: 5. FDC | C30: 5.1 SVID List Check | D30: =FDC!H31 -> 5 | E30: =FDC!I31 -> 5 | F30: =IF(D30<>0, E30/D30, "-") -> 1 | G30: =FDC!J31 -> 0 | H30: =IF(D30<>0, G30/D30, "-") -> 0
C31: 5.2 FDC Set / Reset | D31: =FDC!H103 -> 5 | E31: =FDC!I103 -> 5 | F31: =IF(D31<>0, E31/D31, "-") -> 1 | G31: =FDC!J103 -> 0 | H31: =IF(D31<>0, G31/D31, "-") -> 0
C32: FDC Sub Total | D32: =SUM(D30:D31) -> 10 | E32: =SUM(E30:E31) -> 10 | F32: =IF(D32<>0, E32/D32, "-") -> 1 | G32: =SUM(G30:G31) -> 0 | H32: =IF(D32<>0, G32/D32, "-") -> 0
B33: 6. Alarm | C33: 6.1 Alarm Report | D33: =Alarm!H12 -> 2 | E33: =Alarm!I12 -> 2 | F33: =IF(D33<>0, E33/D33, "-") -> 1 | G33: =Alarm!J12 -> 0 | H33: =IF(D33<>0, G33/D33, "-") -> 0
C34: 6.2 Multi Alarm & List Check | D34: =Alarm!H125 -> 3 | E34: =Alarm!I125 -> 3 | F34: =IF(D34<>0, E34/D34, "-") -> 1 | G34: =Alarm!J125 -> 0 | H34: =IF(D34<>0, G34/D34, "-") -> 0
C35: 6.3 Unit Alarm Report | D35: =Alarm!H201 -> 0 | E35: =Alarm!I201 -> 0 | F35: =IF(D35<>0, E35/D35, "-") -> - | G35: =Alarm!J201 -> 0 | H35: =IF(D35<>0, G35/D35, "-") -> -
C36: Alarm Sub Total | D36: =SUM(D33:D34) -> 5 | E36: =SUM(E33:E34) -> 5 | F36: =IF(D36<>0, E36/D36, "-") -> 1 | G36: =SUM(G33:G34) -> 0 | H36: =IF(D36<>0, G36/D36, "-") -> 0
B37: 7. EQP State | C37: 7.1 EQP State Change | D37: ='EQP State'!H12 -> 8 | E37: ='EQP State'!I12 -> 7 | F37: =IF(D37<>0, E37/D37, "-") -> 0.875 | G37: ='EQP State'!J12 -> 0 | H37: =IF(D37<>0, G37/D37, "-") -> 0
C38: 7.2 Unit State Change | D38: ='EQP State'!H502 -> 0 | E38: ='EQP State'!I502 -> 0 | F38: =IF(D38<>0, E38/D38, "-") -> - | G38: ='EQP State'!J502 -> 0 | H38: =IF(D38<>0, G38/D38, "-") -> -
C39: EQP State Sub Total | D39: =SUM(D37:D38) -> 8 | E39: =SUM(E37:E38) -> 7 | F39: =IF(D39<>0, E39/D39, "-") -> 0.875 | G39: =SUM(G37:G38) -> 0 | H39: =IF(D39<>0, G39/D39, "-") -> 0
B40: 8. Cell Tracking | C40: 8.1 Start Cell Lot | D40: =Tracking!H12 -> 0 | E40: =Tracking!I12 -> 0 | F40: =IF(D40<>0, E40/D40, "-") -> - | G40: =Tracking!J12 -> 0 | H40: =IF(D40<>0, G40/D40, "-") -> -
C41: 8.2 Normal Cell Tracking | D41: =Tracking!H59 -> 5 | E41: =Tracking!I59 -> 5 | F41: =IF(D41<>0, E41/D41, "-") -> 1 | G41: =Tracking!J59 -> 0 | H41: =IF(D41<>0, G41/D41, "-") -> 0
C42: 8.3 Cell Information Request | D42: =Tracking!H210 -> 0 | E42: =Tracking!I210 -> 0 | F42: =IF(D42<>0, E42/D42, "-") -> - | G42: =Tracking!J210 -> 0 | H42: =IF(D42<>0, G42/D42, "-") -> -
...

Sheet Title & Summary
B1: 대외비 2020.07.13/송지훈 프로/모듈IT그룹
C5: EQUIPMENT ONLINE CHECK LIST
C7: For SDC Equipment Automation
J8: 설비명 D_LAMI AUTOMATIVE (AP SYSTEMS)
E10: 출하 전 검수 | G10: =IF(IF(H22="-",1,H22)*IF(H27="-",1,H27)<1,IF(H29=0,"","FAIL"),IF(H29>=0.9,"PASS",IF(H29=0,"","FAIL"))) -> PASS | H10: 입고 후 검수 | J10: =IF(J29>=1,"PASS",IF(J29=0,"","FAIL"))
C12: ONLINE 기능 구분 | E12: 필요 자재 | F12: 전체 기능 | G12: 출하 전 검수 | I12: 입고 후 검수
G13: 전체기능 | I13: 전체기능
G14: OK | H14: Rate | I14: OK | J14: Rate
C15: 1. Online 통신 연결 | F15: ='Scenario Check Summary'!D16 -> 3 | G15: ='Scenario Check Summary'!E16 -> 3 | H15: ='Scenario Check Summary'!F16 -> 1 | I15: ='Scenario Check Summary'!G16 -> 0 | J15: ='Scenario Check Summary'!H16 -> 0
C16: 2. 초기화, 설비상태 확인 | F16: ='Scenario Check Summary'!D19 -> 8 | G16: ='Scenario Check Summary'!E19 -> 8 | H16: ='Scenario Check Summary'!F19 -> 1 | I16: ='Scenario Check Summary'!G19 -> 0 | J16: ='Scenario Check Summary'!H19 -> 0
C17: 3. RMS | F17: ='Scenario Check Summary'!D25 -> 21 | G17: ='Scenario Check Summary'!E25 -> 21 | H17: ='Scenario Check Summary'!F25 -> 1 | I17: ='Scenario Check Summary'!G25 -> 0 | J17: ='Scenario Check Summary'!H25 -> 0
C18: 4. ECM | F18: ='Scenario Check Summary'!D29 -> 5 | G18: ='Scenario Check Summary'!E29 -> 5 | H18: ='Scenario Check Summary'!F29 -> 1 | I18: ='Scenario Check Summary'!G29 -> 0 | J18: ='Scenario Check Summary'!H29 -> 0
C19: 5. FDC | E19: Cell | F19: ='Scenario Check Summary'!D32 -> 10 | G19: ='Scenario Check Summary'!E32 -> 10 | H19: ='Scenario Check Summary'!F32 -> 1 | I19: ='Scenario Check Summary'!G32 -> 0 | J19: ='Scenario Check Summary'!H32 -> 0
C20: 6. Alarm 보고, 조회 | F20: ='Scenario Check Summary'!D36 -> 5 | G20: ='Scenario Check Summary'!E36 -> 5 | H20: ='Scenario Check Summary'!F36 -> 1 | I20: ='Scenario Check Summary'!G36 -> 0 | J20: ='Scenario Check Summary'!H36 -> 0
C21: 7. 설비 상태, Interlock | E21: Cell | F21: ='Scenario Check Summary'!D39 -> 8 | G21: ='Scenario Check Summary'!E39 -> 7 | H21: ='Scenario Check Summary'!F39 -> 0.875 | I21: ='Scenario Check Summary'!G39 -> 0 | J21: ='Scenario Check Summary'!H39 -> 0
C22: 8. Cell Tracking | E22: Cell, 자재 | F22: ='Scenario Check Summary'!D46 -> 5 | G22: ='Scenario Check Summary'!E46 -> 5 | H22: ='Scenario Check Summary'!F46 -> 1 | I22: ='Scenario Check Summary'!G46 -> 0 | J22: ='Scenario Check Summary'!H46 -> 0
C23: 9. 자재 관리 | E23: 자재 | F23: ='Scenario Check Summary'!D53 -> 21 | G23: ='Scenario Check Summary'!E53 -> 21 | H23: ='Scenario Check Summary'!F53 -> 1 | I23: ='Scenario Check Summary'!G53 -> 0 | J23: ='Scenario Check Summary'!H53 -> 0
C24: 10. APC | E24: Cell | F24: ='Scenario Check Summary'!D57 -> 6 | G24: ='Scenario Check Summary'!E57 -> 5 | H24: ='Scenario Check Summary'!F57 -> 0.83333333 | I24: ='Scenario Check Summary'!G57 -> 0 | J24: ='Scenario Check Summary'!H57 -> 0
C25: 11. Operator Call | F25: ='Scenario Check Summary'!D60 -> 2 | G25: ='Scenario Check Summary'!E60 -> 2 | H25: ='Scenario Check Summary'!F60 -> 1 | I25: ='Scenario Check Summary'!G60 -> 0 | J25: ='Scenario Check Summary'!H60 -> 0
C26: 12. Interlock | F26: ='Scenario Check Summary'!D64 -> 2 | G26: ='Scenario Check Summary'!E64 -> 1 | H26: ='Scenario Check Summary'!F64 -> 0.5 | I26: ='Scenario Check Summary'!G64 -> 0 | J26: ='Scenario Check Summary'!H64 -> 0
C27: 13. Carrier Process | E27: Cell, Tray | F27: ='Scenario Check Summary'!D73 -> 6 | G27: ='Scenario Check Summary'!E73 -> 6 | H27: ='Scenario Check Summary'!F73 -> 1 | I27: ='Scenario Check Summary'!G73 -> 0 | J27: ='Scenario Check Summary'!H73 -> 0
C28: 14. 기타 기능 | F28: ='Scenario Check Summary'!D81 -> 3 | G28: ='Scenario Check Summary'!E81 -> 3 | H28: ='Scenario Check Summary'!F81 -> 1 | I28: ='Scenario Check Summary'!G81 -> 0 | J28: ='Scenario Check Summary'!H81 -> 0
C29: TOTAL | F29: =SUM(F15:F28) -> 105 | G29: =SUM(G15:G28) -> 102 | H29: =G29/F29 -> 0.97142857 | I29: =SUM(I15:I28) -> 0 | J29: =I29/F29 -> 0
C30: ※ Cell Tracking / Carrier Process 사용 설비는 해당 항목 100% 완료 필수 (미진시, PASS 불가)
I32: TEST DATE :
I33: MODULE TYPE :
I34: EQ MAKER : | J34: AP SYSTEMS
I35: EQ MAKER SOFT ENG'R :
I36: SDC EQUIPMENT ENG'R :
I37: SDC FA ENG'R :
G39: SMART IT TEAM
G40: SAMSUNG DISPLAY CO., LTD.

Sheet Port Reference
B1: 대외비 2020.07.13/송지훈 프로/모듈IT그룹
B2: IN-PORT
B3: Seqeunce | C3: Case | D3: 설비 동작 | E3: 상황 도해 | F3: Zone 별 상황 | G3: Event | H3: Description | I3: Key Data | J3: Remarks
B4: 1 | C4: Tray Load (AGV) NORMAL | D4: AGV 도착 → PIO 진행 → Tray 도착 감지 (Sensor ON) | F4: 1) A-zone PIO 후 Tray 도착 2) B-zone Don't Care | G4: S6F11 CEID=351 | H4: Load Complete | I4: JOBID='PRELOAD' | J4: V3는 'PRELOAD' TPJT는 실물 TrayID
C5: Tray Load (사람) ABNORMAL | D5: 사람이 Tray Load → Tray 도착 감지 (Sensor ON) | F5: 1) A-zone Tray 도착 2) B-zone Don't Care | G5: S6F11 CEID=351 | H5: Load Complete | I5: JOBID='PRELOAD' | J5: V3는 'PRELOAD' TPJT는 실물 TrayID
B6: 1-1 | C6: Tray 제거 (사람) ABNORMAL | D6: 사람이 Tray 제거 → A-zone Sensor OFF | F6: 1) A-zone Tray 없어짐 → B-zone으로 이동 동작 없음 2) B-zone Don't Care | G6: S6F11 CEID=350 | H6: Load Request | I6: JOBID=NULL
B7: 2 | C7: Tray 이동 (설비) NORMAL | D7: A-zone에서 B-zone으로 Tray 이동 → B-zone 도착 | F7: 1) A-zone Tray 없어짐 2) B-zone Tray 도착 ※ 설비 제어 시퀀스로 구동된 상황 | G7: - | H7: - | I7: -
B8: 3 | C8: MCR Read (설비) NORMAL | D8: B-zone에서 MCR로 Tray ID Read 완료 | F8: 1) A-zone Don't Care → A-zone에 다른 Tray 도착 시 : Case 1/2 2) B-zone Lift 상승 및 MCR Read | G8: S6F11 CEID=351 S6F11 CEID=262 | H8: Load Complete Car. Info. Request | I8: JOBID=TRAYID CARRIERID=TRAYID
B9: 3-1 | C9: 5번 후 조건 분기 NORMAL | D9: S6F11 CEID=262 보고 → S3F115 수신 (PASS) A-zone 비어있음 | F9: 1) A-zone 비어있음 2) B-zone Case 3 상황 후 | G9: S6F11 CEID=350 | H9: Load Request | I9: JOBID=NULL
B10: 3-2 | C10: 5번 후 조건 분기 NORMAL | D10: S6F11 CEID=262 보고 → S3F115 수신 (PASS) A-zone Tray 존재 | F10: 1) A-zone Tray 존재 → Case 1/2에 의해 이미 Load Complete 보고 2) B-zone Case 3 상황 후 | G10: - | H10: - | I10: -
B11: 3-3 | C11: 5번 후 조건 분기 ABNORMAL | D11: S6F11 CEID=262 보고 → S3F115 수신 (FAIL) A-zone Tray 존재 여부 Don't Care | F11: 1) A-zone Don’t' Care 2) B-zone Case 3 상황 후 | G11: S5F1 | H11: Alarm Report | I11: Serious Alarm (투입 불가) (Tray 제거 필요)
B12: 비정규 | C12: 강제 제거 ABNORMAL | D12: B-zone에서 투입 중 → 설비 Muting 버튼 누름 → Lifter 하강 → 사람이 강제로 Tray를 A-zone으로 끌어냄 | F12: 1) A-zone Tray 인식 2) B-zone Tray 강제 제거 | G12: S6F11 CEID=351 | H12: Load Complete | I12: JOBID='PRELOAD' | J12: . 제어 가능한 경우 Event 발생하지 않는 것이 좋음 . 이 상태에서 재투입 불가
B13: 비정규 | C13: 설비 상태 변경 (Down → Up) ABNORMAL | D13: 설비 상태가 Down에서 Up으로 변경된 경우 A-zone 비어있음 | F13: 1) A-zone 비어있음 2) B-zone Don’t' Care | G13: S6F11 CEID=350 | H13: Load Request | I13: JOBID=NULL | J13: . 설비 Down → Up 도중에 CIM OFFLINE 발생했을 경우 대비하여 보정 Event
D14: 설비 상태가 Down에서 Up으로 변경된 경우 A-zone Tray 존재 | F14: 1) A-zone Tray 인식 2) B-zone Don’t' Care | G14: - | H14: - | I14: -
B16: OUT-PORT
B17: No | C17: Case | D17: 설비 동작 | E17: 상황 도해 | F17: Zone 별 상황 | G17: Event | H17: Description | I17: Key Data | J17: Remarks
B18: 1 | C18: Batch 구성 (설비) NORMAL | D18: C-zone에서 빈 Tray 적층 완료 → 뚜껑 Tray 덮음 | F18: 1) C-zone Batch 구성 완료 2) D-zone Don't Care | G18: S6F11 CEID=260 | H18: Car. Assign Request | I18: CARRIERID SUBCARRIERID CARRIERTYPE='11'
C19: Batch 구성 (설비) ABNORMAL | D19: C-zone에서 빈 Tray 적층 중 사람이 강제종료 버튼 누름 → 뚜껑 Tray 덮음 | F19: 1) C-zone Batch 구성 완료 2) D-zone Don't Care | G19: S6F11 CEID=260 | H19: Car. Assign Request | I19: CARRIERID SUBCARRIERID CARRIERTYPE='13'
B20: 2 | C20: Tray 이동 (설비) NORMAL | D20: C-zone Lifter 하강 → C-zone에서 D-zone으로 Tray 이동 → D-zone 도착 감지 (Sensor ON) | F20: 1) C-zone Tray 없어짐 2) D-zone Tray 도착 ※ 설비 제어 시퀀스로 구동된 상황 | G20: S6F11 CEID=352 | H20: Unload Request | I20: JOBID=TRAYID
B21: 3 | C21: Tray 배출 (AGV) NORMAL | D21: AGV 도착 → PIO 진행 → Tray 배출 감지 (Sensor OFF) | F21: 1) C-zone Don't Care 2) D-zone PIO 후 Tray 없어짐 | G21: S6F11 CEID=353 | H21: Unload Complete | I21: JOBID=TRAYID
C22: Tray 배출 (사람) ABNORMAL | D22: 사람이 Tray 제거 → D-zone Sensor OFF | F22: 1) C-zone Don't Care 2) D-zone Tray 없어짐 | G22: S6F11 CEID=353 | H22: Unload Complete | I22: JOBID=TRAYID
B23: 비정규 | C23: 강제 제거 ABNORMAL | D23: C-zone에서 Tray 적재 중 → 설비 Muting 버튼 누름 → Lifter 하강 → 사람이 강제로 Tray를 D-zone으로 끌어냄 | F23: 1) C-zone Tray 강제 제거 2) D-zone Tray 인식 (ID 모름) → 뚜껑 Tray도 덮지 않은 상황 | G23: - | H23: - | I23: - | J23: . Event (Unload Request) 발생 불가 (TRAYID 모름) → 전/실 불일치 발생
D24: 강제로 끌어낸 Tray를 D-zone에서 제거 | F24: 1) C-zone Don't Care 2) D-zone Tray 없어짐 (ID 모름) | G24: - | H24: - | I24: - | J24: . Event (Unload Complete) 발생 불가 (TRAYID 모름) → 전/실 불일치 제거
B25: 비정규 | C25: 임의 적재 ABNORMAL | D25: 사람이 D-zone에 Tray 임의 Load → D-zone Sensor ON | F25: 1) C-zone Don't Care 2) D-zone Tray 인식 (ID 모름) ※ 설비 제어 시퀀스가 아닌 비정상 상황 | G25: - | H25: - | I25: - | J25: . Event (Unload Request) 발생 불가 (TRAYID 모름) → 전/실 불일치 발생
D26: 사람이 D-zone에 Tray 임의 Load한 Tray 사람이 제거 → D-zone Sensor OFF | F26: 1) C-zone Don't Care 2) D-zone Tray 없어짐 (ID 모름) ※ 설비 제어 시퀀스가 아닌 비정상 상황 | G26: - | H26: - | I26: - | J26: . Event (Unload Complete) 발생 불가 (TRAYID 모름) → 전/실 불일치 제거
B27: 비정규 | C27: 설비 상태 변경 (Down → Up) ABNORMAL | D27: 설비 상태가 Down에서 Up으로 변경된 경우 D-zone 비어있음 | F27: 1) A-zone 비어있음 2) B-zone Don’t' Care | G27: - | H27: - | I27: -
D28: 설비 상태가 Down에서 Up으로 변경된 경우 D-zone Tray 존재, ID 아는 경우 | F28: 1) A-zone Tray 인식 2) B-zone Don’t' Care | G28: S6F11 CEID=352 | H28: Unload Request | I28: JOBID=TRAYID | J28: . 설비 Down → Up 도중에 CIM OFFLINE 발생했을 경우 대비하여 보정 Event
D29: 설비 상태가 Down에서 Up으로 변경된 경우 D-zone Tray 존재, ID 모르는 경우 (비정상 적재) | F29: 1) A-zone Tray 인식 2) B-zone Don’t' Care | G29: - | H29: - | I29: -

Sheet Tray Pocket ID Rule
B1: 대외비 2020.07.13/송지훈 프로/모듈IT그룹

Sheet Recipe Security UI
B1: 대외비 2020.07.13/송지훈 프로/모듈IT그룹
B2: 4.3 Level 별 접근 권한 관리
B3: 4.3.1. 등급 구분 : Operator, Engineer, Administrator
B4: 4.3.2. Operator : 자재 Kitting, 생산 수량 확인, 설비 알람 History 등 생산 관련 최소 메뉴만 접근 가능, 설비 조작 불가능 Engineer : Operator 접근 가능 메뉴, 설비 메뉴얼 동작, 설비 Teaching 가능, 주요 Recipe 항목 접근 불가능 Administrator : 전 메뉴 접근 가능 ※ 이 외, USER 와 협의 후 구성 할 것. (UI 구성 예정 항목 → SDC 확인 및 등급별 분류 → UI 구성)
B6: 4.4 보안강화 화면 구성
B7: 4.4.1. Security Control 화면
B8: ● Data Window-Security Control
B9: : Data Key → 데이터 선택창 → Security Control
B38: 4.4.1.1. Screen Close Timer : 대기화면 전환 시간설정 창으로 설정한 시간 도달시 대기화면으로 전환
B39: 4.4.1.2. Password Change : EQ상 사용자 권한별 Password 설정/변경 창
B41: 4.4.2. Login Selection 구성
B67: 4.4.3. Password Check 구성

Sheet Recipe Number 설비 조건
B1: 대외비 2020.07.13/송지훈 프로/모듈IT그룹
B2: 설비 선행 조건
B4: 1) Recipe List PPID 99개 지원 필요
B5: : 단순 누적되며 고정 List 표현 안되어있는 검사기 설비의 경우 PPID 앞에 넘버링 부여 필요
B7: 2) Engineer, Operator Teaching Parameter 선정 ( = Offset)
B8: : Model Change 발생시 Teaching 빈도 높은 값으로 선정 (현업과 협의 필요)
B10: 3) List의 각 PPID 마다 설비에서 별도 관리하는 Offset UI 필요
B11: : Current PPID의 PPID List에 대한 Offset UI 형태로 구성 필요
B12: : Offset의 각 값을 입력, 삭제(0처리), 수정 가능 --- Offset은 설비 내부에서만 관리되는 값으로 입력/수정/삭제시 별도 SECS 메시지 발생은 없음
B13: : 해당 UI에 입력된 Offset 만큼 Recipe Parameter에서 값 가감하여 동작
B14: : ex) 선정된 Offset이 3개라면? 99(PPID List수) * 3(Offset종류) = 297개의 Data 관리 영역 필요
B16: 4) S7F223의 'PPID_NUMBER' 값에 따라 해당 Offset 유지/삭제 처리됨
... B36: → 기존에 Engineer가 PPID List '99번'에 입력해둔 Offset을 유지한채 Body 삭제
B38: S7F223 신규 Message (TC → EQP) | L38: S7F217 신규 Message (EQP → TC)
B39: 2) Message 구조 | L39: <L, 7 | M39: * PPID Event Info
B40: <L, 6 * PPID Send Info | L40: 1.<A[1] | M40: $MODE>
B41: 1.<A[40] $EQPID> * 설비 고유 ID | L41: 2.<A[40] | M41: $EQPID>
B42: 2.<A[40] $MODULEID> * UNIT 고유 ID S7F23 대비 추가 항목 | L42: 3.<A[40] | M42: $MODULE ID>
B43: 3.<A[40] $PPID> * 변경 Process Parameter Group ID (Recipe ID) | L43: 4.<A[40] | M43: $PPID>
B44: 4.<A[1] $PPID_TYPE> * 변경 Process Parameter Group ID (Recipe ID) TYPE | L44: 5.<A[1] | M44: $PPID_TYPE> * 설비에서 변경 된 Process Parameter Group ID (Recipe ID) TYPE
B45: 5.<A[5] $PPID_NUMBER> * Recipe ID 번호 ß 신규추가 | J45: 95N | L45: 6.<A[5] | M45: $PPID_NUMBER>
B46: 6.<L, a * Command Set List a = Number of process commands | L46: 7.<L, a | M46: * Command Set List a = Number of process commands
B47: 1.<L, 2 * CCODE Set | L47: 1.<L, 2 | M47: CCODE Set
B48: 1.<A[3] $CCODE> * | L48: 1.<A[3] | M48: $CCODE> * 생성/수정/삭제 Mode
B49: 2.<L, b * b = Number of parameters | L49: 2.<L, b | M49: * Parameter List b = Number of parameters
B50: 1.<L, 2 * Parameter Set List | L50: 1.<L, 2 | M50: * Parameter Set
B51: 1.<A[40] $PARAMETERNAME> * Parameter 이름 | L51: 1.<A[40] | M51: $P_PARM_NAME>
B52: 2.<A[40] $PARAMETERVALUE> * Parameter 값 | L52: 2.<A[40] | M52: $P_PARM>
B53: *L, b = Parameter의 개수
B56: RECV S7F224 (EQP → TC) | L56: SEND S7F218 (TC → EQP)
B57: <A,1 '0'>. | L57: <A,1V [ACK7] '0'>.

Sheet Get Attr Object Type 정의
A1: 대외비 2020.07.13/송지훈 프로/모듈IT그룹 | E1: 'Carrier Process' Sheet로 돌아가기
B2: ※ Type 정의 및 사용 기준
B3: ① 아래 표에 해당되는 공정은 각 공정별 Object Type을 기준으로 하여 S14F1(Get Attr)에 보고한다.
B4: ② 신규 Object Type이 추가 필요한 경우에는 자동화 담당자와 협의 후 결정 및 반영하여 사용한다.
B6: Line | C6: 공정 | D6: Object Type | E6: Insert Date
B7: MOD | C7: POL 부착기 (CP) | D7: POL | E7: '23 01.26
C8: COP / COF | D8: COP | E8: '23 01.26
C9: FOP / FOF | D9: FOP | E9: '23 01.26
C10: FOB | D10: FOB | E10: '23 01.26
C11: DB-FOP / T-FOG | D11: TFOG | E11: '23 01.26
C12: BPL | D12: BPL | E12: '23 01.26
C13: COS | D13: COS | E13: '23 03.22
C14: CRD | D14: CRD | E14: '23 01.26
C15: LPC | D15: LPC | E15: '23 01.26
C16: LFC | D16: LFC | E16: '23 01.26
C17: D-Sub (진공) | D17: D_SLAMI_VAC | E17: '23 01.26
C18: D-Main (진공) | D18: D_MLAMI_VAC | E18: '23 01.26
C19: D-Sub (inkjet 도포) | D19: D_SLAMI_INK | E19: '23 01.26
... C37: OQC 적재기 | D37: OQC | E37: '23 01.26
B38: CELL | C38: TCG | D38: CELL_TCG | E38: '23 09.01
C39: TLC | D39: CELL_TLC | E39: '23 09.01
C40: TIT | D40: CELL_TIT | E40: '23 09.01
C41: Sorter | D41: CELL_SOR | E41: '23 09.01
C42: AVI | D42: CELL_AVI | E42: '23 09.01
C43: AOT | D43: CELL_AOT | E43: '23 09.01
C44: MVI | D44: CELL_MVI | E44: '23 09.01
C45: ALM | D45: CELL_ALM | E45: '23 09.01
C46: CRP | D46: CELL_CRP | E46: '23 09.01

Sheet Revision
B1: 대외비 2020.07.13/송지훈 프로/모듈IT그룹
F2: 대외비
B3: REVISION HISTORY
B5: NO. | C5: DATE | D5: DESCRIPTION | E5: SHEET | F5: REMARK
B6: 1 | C6: 43020 | D6: Machine 대응 Event 정의 및 V1.18 반영 | E6: Stream Function | F6: V0.1
B7: 2 | C7: 43041 | D7: Interlock Type 별 Scenario 및 Unit Interlock 기준 추가 | E7: Interlock | F7: V1.1
B8: 3 | C8: 43047 | D8: Material Cancel (By Host) 검증 항목 추가 | E8: Material | F8: V1.2
B9: 4 | C9: 43048 | D9: Unit Alarm / Unit OP Call 검증 항목 추가 | E9: Alarm, OP Call | F9: V1.2
B10: 5 | C10: 43049 | D10: Unit State 검증 항목 추가 | E10: EQP State | F10: V1.3
B11: 6 | C11: 43052 | D11: Tower Lamp 동작 기준 추가, Port 참조 정보 추가 | E11: Eqp State | F11: V1.4
B12: 7 | C12: 43080 | D12: Interlock Type 별 Multi 발생 시 Scenario 및 Message 내용 기준 추가 | E12: EQP State | F12: V1.5
B13: 8 | C13: 43102 | D13: Load Port 기준 정보 수정 | E13: EQP State | F13: V1.5
B14: 9 | C14: 43215 | D14: Version 표준 - HSMS Message Spec V1.18 기준 | E14: - | F14: V1.18
B15: 10 | C15: 43363 | D15: Version 표준 - HSMS Message Spec V1.19 기준 | E15: - | F15: V1.19
B16: 11 | C16: 43439 | D16: EQP Interlock (Multi) Check Item 내용 수정 | E16: EQP State | F16: V1.19
B17: 12 | C17: 43439 | D17: Code Information Request Check Item 내용 수정 | E17: Tracking | F17: V1.19
... B107: 102 | C107: 45338 | D107: Cell ICC 설비 Tracking 대응을 위한 '15.8 Carrier Process Report For Normal Process (Cell EQP - CST Unloader)' 추가 | E107: Carrier Process | F107: V1.22.0

Sheet ISSUE
B1: 대외비 2020.07.13/송지훈 프로/모듈IT그룹
I2: 대외비
B3: ISSUE HISTORY
B5: No. | C5: DATE | D5: Sheet Name | E5: Message.1 | F5: Message.2 | G5: 내용 | H5: 완료여부 | I5: 비고
B6: 1 | C6: 45973 | D6: Initial | E6: S2F17 | G6: VISION PC 시간 동기화 안됨 | H6: X
C7: 45973 | D7: FUNCTION | E7: S6F11 | F7: CEID : 110 | G7: 화면에 RESERVED지워야됨 | H7: O
C8: 45973 | D8: 0

Sheet Connection
B1: 대외비 2020.07.13/송지훈 프로/모듈IT그룹
J2: 대외비
B3: Scenario Check List 1 - Connection
B5: 처음으로 | H5: Use | I5: Pass | J5: Progress
G6: 출하 검수 | H6: =H12+H85+H146 -> 3 | I6: =I12+I85+I146 -> 3 | J6: =I6/H6 -> 1
G7: Line Test | H7: =H6 -> 3 | I7: =J12+J85+J146 -> 0 | J7: =I7/H7 -> 0
B9: 1.1 Host - EQ Connection
H10: Use | I10: Result
I11: 출하 검수 | J11: Line Test
H12: =COUNTIF(H15:H80, "O") -> 1 | I12: =COUNTIF(I15:I80, "O") -> 1 | J12: =COUNTIF(J15:J80, "O") -> 0
B14: Host | D14: EQ | F14: Check Item | H14: Use | I14: 출하 검수 | J14: Line Test
B15: 사전 준비 작업 | F15: 1) Simulator IP 설정 : 설비 IP를 참조하여 동일한 Gateway 내의 IP로 설정
F16: - CIM PC가 설비 內 Hub에 연결되어 있는 경우, 설비 內 타 제어기 IP와 충돌 주의
F17: 2) HSMS Parameter 설정
F18: - DeviceID : 1
F19: - Connection Port : 8000
F20: - Connection Mode 설정 (Host : Active, EQ : Passive)
F21: 3) 설비 CIM PC, Host Simulator 간 LAN 선 연결
B23: Ping Test | H23: O | I23: O
B25: Ping Test
F26: 1) Simulator Command Window 사용
D27: Ping Reply
D30: Ping Test | F30: 2) 설비 CIM 측 Command Window 사용
B32: Ping Reply
B35: Connection | F35: 1) 설비 CIM Software 기동
F36: 2) Host Simulator 기동
F37: 3) Open Connection 시도
B39: Connect Request
D41: Connect Response | F41: SECS1 Log 확인
B44: Select Request
D46: Select Response | F46: SECS1 Log 확인
B49: Separate | F49: 1) 설비 CIM Software 종료
D51: Separate Request | F51: SECS1 Log 확인
B53: Separate Response
B56: Keeping Connection | F56: 1) Dummy Hub에 설비 CIM PC, Host Simulator 1, 2를 연결함
F57: (복수의 Simulator 사용)
F58: 2) 설비 CIM PC와 simulator 1 간 Session이 연결된 상태에서 Simulator2로 연결 시도
F59: (IP, Port, DeviceID 등 Parameter 정상)
B61: Connect Request
D63: Connect Response | F63: SECS1 Log 확인 : Fail → 기존 Connection 유지
...

Sheet Initial
B1: 대외비 2020.07.13/송지훈 프로/모듈IT그룹
J2: 대외비
B3: Scenario Check List 2 - Initializing
B5: 처음으로 | H5: Use | I5: Pass | J5: Progress
G6: 출하 검수 | H6: =H26+H56 -> 8 | I6: =I26+I56 -> 8 | J6: =I6/H6 -> 1
G7: Line Test | H7: =H6 -> 8 | I7: =J26+J56 -> 0 | J7: =I7/H7 -> 0
B9: ※ 설비 HMI(UI) 필수 구현 정보
B10: * Main UI에 구현되어 있어야 하며, Sub UI 구현 여부는 자유
B11: ① 설비상태
B12: . 각 State별 현재 상태에 맞는 값을 보여주면 됨
B13: 예시) 좌측 : Run 투입 + 공정 진행중인 상태, 우측 : Run 미투입 + Interlock 발생 상태
B19: ② Current PPID
B20: ③ 년월일 시간
B21: ④ EQP ID
B23: 2.1 Initial Communication
H24: Use | I24: Result
I25: 출하 검수 | J25: Line Test
H26: =COUNTIF(H29:H51, "O") -> 2 | I26: =COUNTIF(I29:I51, "O") -> 2 | J26: =COUNTIF(J29:J51, "O") -> 0
B28: Host | D28: EQ | F28: Check Item | H28: Use | I28: 출하 검수 | J28: Line Test
B29: 사전 준비 작업 | F29: 1) 설비에 사용 가능한 자재를 설비 밖에 준비 (즉시 장착 가능)
F30: 2) 투입 가능한 Cell을 설비 밖에 준비 (즉시 장착 가능)
F31: 3) 설비는 Alarm이 없는 정상 Idle 상태로 대기
B33: Initial Connection | F33: 1) 설비 Online 연결 | H33: O | I33: O
D35: S1F1 | F35: Are You There
B37: S1F2 | F37: I'm Here
D40: S6F11 | F40: CEID=106 : On-Line Remote
B42: S6F12
B45: Time Sync | H45: O | I45: O
D47: S2F17 | F47: Date and Time Request
B49: S2F18 | F49: Date and Time Date
F50: 설비의 모든 화면(Vision, 검사 PC 포함)에 시간이 정상 반영되어야 함
F51: * 불가한 경우 자동화 담당자와 협의
B53: 2.2 Equipment Current State Check
H54: Use | I54: Result
I55: 출하 검수 | J55: Line Test
H56: =COUNTIF(H59:H463, "O") -> 6 | I56: =COUNTIF(I59:I463, "O") -> 6 | J56: =COUNTIF(J59:J463, "O") -> 0
B58: Host | D58: EQ | F58: Check Item | H58: 대상 | I58: 출하 검수 | J58: Line Test
B61: Equipment State Request | F61: EQP State Sheet Check | H61: O | I61: O
B64: EQP : Normal, Idle, Run | F64: 1) 설비를 아래 상태로 설정한 후 State를 조회한다
F65: - AVAILABILITYSTATE = UP (2)
...

Sheet RMS
B1: 대외비 2020.07.13/송지훈 프로/모듈IT그룹
J2: 대외비
B3: Scenario Check List 3 - RMS
B5: 처음으로 | H5: Use | I5: Pass | J5: Progress
G6: 출하 검수 | H6: =H34+H96+H162+H190+H209 -> 21 | I6: =I34+I96+I162+I190+I209 -> 21 | J6: =I6/H6 -> 1
G7: Line Test | H7: =H6 -> 21 | I7: =J34+J96+J162+J190+J209 -> 0 | J7: =I7/H7 -> 0
B9: ※ RMS UI 구현 정보
B10: * 설비에서 보고하는 값과 UI값 동일 하여야 함 (소수점 포함)
G13: PPID_NUM 사용여부 | I13: O | J13: 1
I14: X
B23: ※ Reserve 영역은 제외하고 구현하여야 함
B25: ※ Recipe Black Box 적용 대상 설비 UI 구현 정보
B26: * Recipe Security UI Sheet 참조
B28: ※ Recipe Number 적용 대상 설비 구현 정보
B29: * Recipe Number 설비 조건 Sheet 참조
B31: 3.1 PPID List & Recipe Body Check
H32: Use | I32: Result
I33: 출하 검수 | J33: Line Test
H34: =COUNTIF(H37:H91, "O") -> 4 | I34: =COUNTIF(I37:I91, "O") -> 4 | J34: =COUNTIF(J37:J91, "O") -> 0
B36: Host | D36: EQ | F36: Check Item | H36: Use | I36: 출하 검수 | J36: Line Test
B37: 사전 준비 작업 | F37: 1) 설비에는 2개 이상의 Recipe가 사전에 작성되어 있어야 함
F38: 2) OSS File을 확보하여 Recipe Body List를 사전에 결정함
B40: PPID List Check | H40: O | I40: O
B42: S7F101 | F42: Current Equipment PPID List Request : PPID_TYPE=1
D44: S7F102 | F44: 실제 설비 화면 상 상태와 보고 내용 일치 여부 확인
B47: Abnormal Case | F47: 1) 사용하지 않는 PPID_TYPE으로 조회 | H47: O | I47: O
B49: S7F101 | F49: Current Equipment PPID List Request : PPID_TYPE=2
D51: S7F102 | F51: Ln=0로 보고하여야 함
F53: 2) 잘못된 EQPID로 조회
B55: S7F101 | F55: Current Equipment PPID List Request : 설비에 설정된 값과 다른 EQPID
D57: S7F102 | F57: Ln=0로 보고하여야 함
B60: Recipe Body Check | F60: 1) 설비에 저장되어 있는 임의의 PPID 1개를 선택하여 조회한다 | H60: O | I60: O
B62: S7F25 | F62: Formatted Process Program Request : PPID_TYPE=1
D64: S7F26 | F64: 실제 설비 화면 상의 PARAMNAME, PARAMVALUE 값과 보고된 값을 비교
F67: 1) 설비에 저장되어 있는 다른 PPID 1개를 더 선택하여 조회한다
B69: S7F25 | F69: Formatted Process Program Request : PPID_TYPE=1
D71: S7F26 | F71: 실제 설비 화면 상의 PARAMNAME, PARAMVALUE 값과 보고된 값을 비교
B74: Abnormal Case | F74: 1) 사용하지 않는 PPID_TYPE으로 조회 | H74: O | I74: O
B76: S7F25 | F76: Formatted Process Program Request : PPID_TYPE=2
D78: S7F26 | F78: Ln=0로 보고하여야 함
...

Sheet ECM
B1: 대외비 2020.07.13/송지훈 프로/모듈IT그룹
J2: 대외비
B3: Scenario Check List 4 - ECM
B5: 처음으로 | H5: Use | I5: Pass | J5: Progress
G6: 출하 검수 | H6: =H28+H90+H128 -> 5 | I6: =I28+I90+I128 -> 5 | J6: =I6/H6 -> 1
G7: Line Test | H7: =H6 -> 5 | I7: =J28+J90+J128 -> 0 | J7: =I7/H7 -> 0
B9: ※ ECM UI 구현 정보
B10: * 설비에서 보고하는 값과 UI값 동일 하여야 함 (소수점 포함)
B23: ※ Reserve 영역은 제외하고 구현하여야 함
B25: 4.1 ECID List Check
H26: Use | I26: Result
I27: 출하 검수 | J27: Line Test
H28: =COUNTIF(H31:H86, "O") -> 4 | I28: =COUNTIF(I31:I86, "O") -> 4 | J28: =COUNTIF(J31:J86, "O") -> 0
B30: Host | D30: EQ | F30: Check Item | H30: Use | I30: 출하 검수 | J30: Line Test
B31: 사전 준비 작업 | F31: 1) 각 EC는 설비가 정상 동작할 수 있는 값으로 사전에 설정되어 있어야 함
F32: 2) OSS File을 확보하여 EC List를 사전에 결정함
B34: EC List Check | F34: 1) 전체 EC를 조회한다 | H34: O | I34: O
B36: S2F13 | F36: Equipment Constant Request : All (Ln=0)
D38: S2F14 | F38: 설비 화면에서 조회되는 List/값이 보고된 값과 일치하여야 함
F39: EC 항목은 OSS 제출 항목과 동일하여야 함
F41: 2) 특정 EC를 조회한다
B43: S2F13 | F43: Equipment Constant Request : 설비에서 관리하는 특정 EC만 설정
D45: S2F14 | F45: 설비 화면에서 조회되는 List/값이 보고된 값과 일치하여야 함
B48: Abnormal Case | F48: 1) 설비에서 관리하지 않는 EC로 조회 | H48: O | I48: O
B50: S2F13 | F50: Equipment Constant Request : 관리 EC, 비관리 EC 섞어서 조회
D52: S2F14 | F52: Ln=0로 보고하여야 함
F54: 2) 잘못된 EQPID로 조회
B56: S2F13 | F56: Equipment Constant Request : 설비에 설정된 값과 다른 EQPID
D58: S2F14 | F58: Ln=0로 보고하여야 함
B61: EC List Check | F61: 1) 전체 EC를 조회한다 | H61: O | I61: O
B63: S2F29 | F63: Equipment Constant Name List Request : All (Ln=0)
D65: S2F30 | F65: 설비 화면에서 조회되는 List/값이 보고된 값과 일치하여야 함
F66: EC 항목은 OSS 제출 항목과 동일하여야 함
F67: ※ ECID 중복 점검표(Log → Sheet) 바로가기
F68: 2) 특정 EC를 조회한다
B70: S2F29 | F70: Equipment Constant Name List Request : 설비에서 관리하는 특정 EC만 설정
D72: S2F30 | F72: 설비 화면에서 조회되는 List/값이 보고된 값과 일치하여야 함
B75: Abnormal Case | F75: 1) 설비에서 관리하지 않는 EC로 조회 | H75: O | I75: O
B77: S2F29 | F77: Equipment Constant Name List Request : 관리 EC, 비관리 EC 섞어서 조회
D79: S2F30 | F79: Ln=0로 보고하여야 함
...

Sheet FDC
B1: 대외비 2020.07.13/송지훈 프로/모듈IT그룹
J2: 대외비
B3: Scenario Check List 5 - FDC
B5: 처음으로 | H5: Use | I5: Pass | J5: Progress
G6: 출하 검수 | H6: =H31+H103 -> 10 | I6: =I31+I103 -> 10 | J6: =I6/H6 -> 1
G7: Line Test | H7: =H6 -> 10 | I7: =J31+J103 -> 0 | J7: =I7/H7 -> 0
B9: ※ FDC UI 구현 정보
B10: * 설비에서 보고하는 값과 UI값 동일 하여야 함 (소수점 포함)
B23: ① INPUT : Sensor에서 읽어들인 값
B24: ② MIDDLE : 내부 변환 처리한 값
B25: ③ OUTPUT : Host로 보고하는 값
B26: ※ Reserve 영역은 제외하고 구현하여야 함
B28: 5.1 SVID List Check
H29: Use | I29: Result
I30: 출하 검수 | J30: Line Test
H31: =COUNTIF(H34:H98, "O") -> 5 | I31: =COUNTIF(I34:I98, "O") -> 5 | J31: =COUNTIF(J34:J98, "O") -> 0
B33: Host | D33: EQ | F33: Check Item | H33: Use | I33: 출하 검수 | J33: Line Test
B34: 사전 준비 작업 | F34: 1) OSS File을 확보하여 SV List를 사전에 결정함
B36: SV Monitoring View (Touch) | F36: 1) 각 SV 별 Sensor Input, 내부 관리, Melsec Output Memory Address 정보를 | H36: O | I36: O
F37: 한눈에 볼 수 있도록 표 형식의 Monitoring 화면을 제공하여야 함
F38: 2) 각 SV 별 Sensor Input, 내부 관리, Melsec Output Memory는 동일한 값을
F39: 유지하여야 함
F40: 3) Monitoring 화면의 각 SV 별 Data가 유효한 값인지 판단하여야 함 (SDC 설비 Eng'r)
B42: SV List Check | F42: 1) 설비 내 전체 SV List를 조회한다 | H42: O | I42: O
B44: S1F3 | F44: Selected Equipment State Request : All (Ln=0)
D46: S1F4 | F46: Message 내의 SV List와 Name이 아래 두가지 항목과 일치하여야 함
F47: OSS (Online Spec Summary) File의 SV List, Name
F48: 설비 화면 (Touch)의 SV Monitoring 화면의 SV List, Name
F50: 2) 설비에서 관리하는 SV 중 일부 List만 조회한다
B52: S1F3 | F52: Selected Equipment State Request : 특정 SV List
D54: S1F4 | F54: Message 내의 SV List와 Name이 아래 두가지 항목과 일치하여야 함
F55: OSS (Online Spec Summary) File의 SV List, Name
F56: 설비 화면 (Touch)의 SV Monitoring 화면의 SV List, Name
B58: Abnormal Case | F58: 1) 설비에서 관리하지 않는 SV로 조회 | H58: O | I58: O
B60: S1F3 | F60: Selected Equipment State Request : 관리 SV, 비관리 SV 섞어서 조회
D62: S1F4 | F62: Ln=0로 보고하여야 함
F64: 2) 잘못된 EQPID로 조회
B66: S1F3 | F66: Selected Equipment State Request : 설비에 설정된 값과 다른 EQPID
D68: S1F4 | F68: Ln=0로 보고하여야 함
B71: SV List Check | F71: 1) 설비 내 전체 SV List를 조회한다 | H71: O | I71: O
...

Sheet Alarm
B1: 대외비 2020.07.13/송지훈 프로/모듈IT그룹
J2: 대외비
B3: Scenario Check List 6 - Alarm
B5: 처음으로 | H5: Use | I5: Pass | J5: Progress
G6: 출하 검수 | H6: =H12+H125+H201 -> 5 | I6: =I12+I125+I201 -> 5 | J6: =I6/H6 -> 1
G7: Line Test | H7: =H6 -> 5 | I7: =J12+J125+J201 -> 0 | J7: =I7/H7 -> 0
B9: 6.1 Alarm Report
H10: Use | I10: Result
I11: 출하 검수 | J11: Line Test
H12: =COUNTIF(H15:H120, "O") -> 2 | I12: =COUNTIF(I15:I120, "O") -> 2 | J12: =COUNTIF(J15:J120, "O") -> 0
B14: Host | D14: EQ | F14: Check Item | H14: Use | I14: 출하 검수 | J14: Line Test
B16: Alarm Text Naming Rule | F16: 1) 설비 Alarm Text는 아래 Naming Rule 형태로 보고되어야 한다.
F17: ※예시) Cylinder Alarm은 CY_LOADER_LOADTRAY_SEPARATION2_CYLINDER_FWD
F19: 1.Alarm 명은 영문 대문자로만 표현한다.
F20: 2.Description은 Category, Position, Device 는 반드시 포함해 4개 이상의
F21: 항목으로 표현하고 항목 사이는 “_“ 로 표현한다.
F22: 3.1번째 Category는 Miss Report외에는 반드시 2자리 영문자로 구성해야 하며
F23: 16개 Category로 한정 한다.
F24: 2번째 Position과 3번째 Device의 경우 아래 Alarm Name Rule의 예제와 같이
F25: Full Name으로 표현한다. (올바른 표현: LOADER, 잘못된 표현: LD)
F26: 4 . 필요시 4번째 Description 1의 경우 Device의 위치에 대해 표기하며
F27: 5번째 Description 2의 경우 위치에 대한 추가 설명을 넣는다
F28: (위치 예: LEFT, 1 등)
F29: 5 . 특수 기호의 경우 병렬 UNIT 표현, SDC 고유 용어, 고유 표현을 위해
... F55: 2-1. Naming Rule 정의
B78: Light Alarm Set / Reset | F78: 1) 설비를 조작하여 경 Alarm 1개를 발생 시킨다 | H78: O | I78: O
D80: S5F1 | F80: Alarm Report Send
F81: 설비 화면에 발생한 Alarm 정보와 보고된 내용이 일치하는지 확인
B83: S5F2 | F83: Alarm Report Aknowledge
F84: 경 Alarm이므로 설비 상태는 변경되면 안 됨
F86: 2) 설비 화면에서 경 Alarm을 해제한다
D88: S5F1 | F88: Alarm Report Send : 해제
F89: 설비 화면에 발생한 Alarm 정보와 보고된 내용이 일치하는지 확인
B91: S5F2 | F91: Alarm Report Aknowledge
B94: Heavy Alarm Set / Reset | F94: 1) 설비를 조작하여 중 Alarm 1개를 발생 시킨다 | H94: O | I94: O
D96: S5F1 | F96: Alarm Report Send
F97: 설비 화면에 발생한 Alarm 정보와 보고된 내용이 일치하는지 확인
B99: S5F2 | F99: Alarm Report Aknowledge
D102: S6F11 | F102: CEID=101 : Equipment Status Change
F103: 설비 각 State 및 설비 Down을 유발한 Alarm 정보 확인
...

Sheet EQP State
B1: 대외비 2020.07.13/송지훈 프로/모듈IT그룹
J2: 대외비
B3: Scenario Check List 7 - EQP State
B5: 처음으로 | H5: Use | I5: Pass | J5: Progress
G6: 출하 검수 | H6: =H12+H502 -> 8 | I6: =I12+I502 -> 7 | J6: =I6/H6 -> 0.875
G7: Line Test | H7: =H6 -> 8 | I7: =J12+J502 -> 0 | J7: =I7/H7 -> 0
B9: 7.1 EQP State Change
H10: Use | I10: Result
I11: 출하 검수 | J11: Line Test
H12: =COUNTIF(H15:H497, "O") -> 8 | I12: =COUNTIF(I15:I497, "O") -> 7 | J12: =COUNTIF(J15:J497, "O") -> 0
B14: Host | D14: EQ | F14: Check Item | H14: Use | I14: 출하 검수 | J14: Line Test
B15: 사전 준비 작업 | F15: ※ 본 Sheet는 他 Sheet의 Test와 병행 진행이 가능함
F16: - ex. Initial, Alarm, Tracking, Interlock 등
F17: 1) Cell 1매를 즉시 투입 가능한 상태로 대기 시킨다
F18: 2) 자재를 사용하는 설비는 자재를 장착하여 Cell이 정상 진행될 수 있도록 준비
B20: 초기화 : Normal, Idle | F20: 1) 설비를 아래 상태로 설정한 후 State를 조회한다 (정상 대기 상태)
F21: - AVAILABILITYSTATE = UP (2)
F22: - INTERLOCKSTATE = OFF (2)
F23: - MOVESTATE = RUNNING (2)
F24: - RUNSTATE = IDLE (1)
B26: S1F5 | F26: SFCD=1 : Equipment State
D28: S1F6 | F28: 실제 설비 화면 상 상태와 보고 내용 일치 여부 확인
B31: EQP Down | F31: 1) 중 Alarm을 발생시켜 설비를 아래 상태로 설정한 후 State를 조회한다 | H31: O | I31: O
D33: S5F1 | F33: Alarm Report Send
F34: 설비 화면에 발생한 Alarm 정보와 보고된 내용이 일치하는지 확인
B36: S5F2 | F36: Alarm Report Aknowledge
D39: S6F11 | F39: CEID=101 : Equipment Status Change
F40: 설비 각 State 및 설비 Down을 유발한 Alarm 정보 확인
F41: - AVAILABILITYSTATE = DOWN (1)
F42: - INTERLOCKSTATE = OFF (2)
F43: - MOVESTATE = PAUSE (1)
F44: - RUNSTATE = IDLE (1)
B46: S6F12
B49: S1F5 | F49: SFCD=1 : Equipment State
D51: S1F6 | F51: 실제 설비 화면 상 상태와 보고 내용 일치 여부 확인
F54: 2) 설비 화면에서 중 Alarm을 해제한다
D56: S5F1 | F56: Alarm Report Send : 해제
F57: 설비 화면에 발생한 Alarm 정보와 보고된 내용이 일치하는지 확인
B59: S5F2 | F59: Alarm Report Aknowledge
F62: 3) 설비를 조작하여 재가동 상태로 만든다
...

Sheet Tracking
B1: 대외비 2020.07.13/송지훈 프로/모듈IT그룹
J2: 대외비
B3: Scenario Check List 8 - Cell Tracking
B5: 처음으로 | H5: Use | I5: Pass | J5: Progress
G6: 출하 검수 | H6: =H12+H59+H210+H232+H299+H334 -> 5 | I6: =I12+I59+I210+I232+I299+I334 -> 5 | J6: =I6/H6 -> 1
G7: Line Test | H7: =H6 -> 5 | I7: =J12+J59+J210+J232+J299+J334 -> 0 | J7: =I7/H7 -> 0
B9: 8.1 Start Cell Lot
H10: Use | I10: Result
I11: 출하 검수 | J11: Line Test
H12: =COUNTIF(H15:H54, "O") -> 0 | I12: =COUNTIF(I15:I54, "O") -> 0 | J12: =COUNTIF(J15:J54, "O") -> 0
B14: Host | D14: EQ | F14: Check Item | H14: 대상 | I14: 출하 검수 | J14: Line Test
B15: 사전 준비 작업 | F15: ※ Batch Lot 관련 설비만 해당됨 (IQC 등)
F16: 1) VCR/MCR/RF 등 ID Reader들은 Setting이 완료되어 Read 가능한 상태여야 함
B18: FAB ID Reading | F18: 1) Tray/Cassette 등을 Load, Batch Lot 정보를 받은 후 Cell ID를 Read 한다
D20: S6F11 | F20: CEID=602 : Start Cell Lot
F21: FAB ID 읽은 값과 보고 내용이 동일하여야 함
B23: S6F12
B26: 정합성 Check | F26: 1) Cell을 20매 이상 연속 투입하여 Cell 정보가 뒤바뀌지 않는지 확인한다
B29: UV Marking Reading | F29: 1) UV Code Marking 후 MCR로 Read 한다
D31: S6F11 | F31: CEID=601 : Reader Result
F32: MCR 읽은 값과 보고 내용이 동일하여야 함
F33: Terminal Msg Timeout 시간 설정 확인하고 Timeout 발생시켜본다. (Default 10sec)
B34: S6F12
B37: 정합성 Check | F37: 1) Cell을 20매 이상 연속 투입하여 Cell 정보가 뒤바뀌지 않는지 확인한다
B40: UV Marking 판정 | F40: 1) UV Marking Reading 결과 OK / NG 판정
B42: PASS Case | F42: 2) PASS Case 인 경우 Cell 정상 Flow
B44: S10F5 | F44: Terminal Display (PASS_SPLIT_CELL ID or TSP ID)
D46: S10F6 | F46: Cell은 정상 Flow 되어야 함
B49: FAIL Case | F49: 2) OK Case 인 경우 Cell 정상 Flow
B51: S10F5 | F51: Terminal Display (FAIL_SPLIT_CELL ID or TSP ID)
D53: S10F6 | F53: Cell은 NG Port로 Flow 되어야 함
B56: 8.2 Normal Cell Tracking
H57: Use | I57: Result
I58: 출하 검수 | J58: Line Test
H59: =COUNTIF(H62:H205, "O") -> 5 | I59: =COUNTIF(I62:I205, "O") -> 5 | J59: =COUNTIF(J62:J205, "O") -> 0
B61: Host | D61: EQ | F61: Check Item | H61: 대상 | I61: 출하 검수 | J61: Line Test
B62: 사전 준비 작업 | F62: ※ 중요 Check Point (Cell, 자재 Tracking)
F63: 1) Cell 20매 연속 투입이 가능하도록 사전 준비하여야 함
B65: Cell Process Start | F65: 1) Cell이 해당 Module로 진입 완료한 시점 (PIO Receive Complete) 또는 | H65: O | I65: O
F66: MCR Read 완료된 시점 (Inline Data 전송 없는 설비)에 발생하여야 함
...

Sheet Material
B1: 대외비 2020.07.13/송지훈 프로/모듈IT그룹
J2: 대외비
B3: Scenario Check List 9 - Material
B5: 처음으로 | H5: Use | I5: Pass | J5: Progress
G6: 출하 검수 | H6: =H12+H170+H209+H288+H404+H437 -> 21 | I6: =I12+I170+I209+I288+I404+I437 -> 21 | J6: =I6/H6 -> 1
G7: Line Test | H7: =H6 -> 21 | I7: =J12+J170+J209+J288+J404+J437 -> 0 | J7: =I7/H7 -> 0
B9: 9.1 Material Kitting
H10: Use | I10: Result
I11: 출하 검수 | J11: Line Test
H12: =COUNTIF(H15:H165, "O") -> 7 | I12: =COUNTIF(I15:I165, "O") -> 7 | J12: =COUNTIF(J15:J165, "O") -> 0
B14: Host | D14: EQ | F14: Check Item | H14: Use | I14: 출하 검수 | J14: Line Test
B15: 사전 준비 작업 | F15: ※ 자재를 사용하는 설비만 해당되는 Scenario임
F16: 1) 설비 자재 Port는 빈 상태로 유지하고, 자재는 바로 장착 가능하도록 준비한다
F17: 2) VCR/MCR/RF 등 자재 ID Reader들은 Setting이 완료되어 Read 가능한 상태여야 함
F18: 3) 설비는 자재를 정상적으로 장착할 수 있도록 Setup이 되어있어야 한다
B20: Material Kitting | F20: 1) 설비에 사용 가능한 자재를 장착한 후 자동/수동으로 ID를 Read 한다 | H20: O | I20: O
D22: S6F11 | F22: CEID=221 : Material Kitting Request
F23: Reader로 읽어들인 자재 Data가 정확히 보고되어야 함
B25: S6F12
F28: 2) Pass Case : 설비에서 자재 관리에 필요한 Data를 입력하여 Message 전송
B29: S3F105 | F29: Material Information Send (Pass)
D31: S3F106
F33: 3) 장착된 자재 State를 조회한다
B35: S1F5 | F35: SFCD=3 : Material State
D37: S1F6 | F37: 실제 설비 화면상 상태와 보고 내용 일치 여부 확인 : 자재 장착
F38: - MATERIALID : 자재 ID
F39: - MATERIALTYPE : 자재 종류
F40: - MATERIALST : MOUNT
F41: - MATERIALPORTID : 자재 장착 위치
F42: - MATERIALUSAGE : 자재 수량 ← 설비 화면 확인
B45: Material Kitting Cancel ① | F45: 1) 설비에 장착되어 사용 가능한 자재를 강제 탈착한다 | H45: O | I45: O
D47: S6F11 | F47: CEID=219 : Material Kitting Cancel Request
F48: 장착되어 사용중인 자재 Data가 정확히 보고되어야 함
B50: S6F12
F52: 2) Pass Case : 설비에서 자재 관리에 필요한 Data를 입력하여 Message 전송
B53: S3F105 | F53: Material Information Send (Pass)
D55: S3F106
F57: 3) 장착된 자재 State를 조회한다
B59: S1F5 | F59: SFCD=3 : Material State
D61: S1F6 | F61: 실제 설비 화면 상 상태와 보고 내용 일치 여부 확인 : 자재 정보 없음
...

Sheet APC
B1: 대외비 2020.07.13/송지훈 프로/모듈IT그룹
J2: 대외비
B3: Scenario Check List 10 - APC
B5: 처음으로 | H5: Use | I5: Pass | J5: Progress
G6: 출하 검수 | H6: =H12+H67+H210 -> 6 | I6: =I12+I67+I210 -> 5 | J6: =I6/H6 -> 0.83333333
G7: Line Test | H7: =H6 -> 6 | I7: =J12+J67+J210 -> 0 | J7: =I7/H7 -> 0
B9: 10.1 Current Control Parameter Check
H10: Use | I10: Result
I11: 출하 검수 | J11: Line Test
H12: =COUNTIF(H15:H62, "O") -> 0 | I12: =COUNTIF(I15:I62, "O") -> 0 | J12: =COUNTIF(J15:J62, "O") -> 0
B14: Host | D14: EQ | F14: Check Item | H14: Use | I14: 출하 검수 | J14: Line Test
B15: 사전 준비 작업 | F15: ※ APC 기능을 지원하는 설비만 해당되는 Scenarion임
F16: 1) 설비에서 지원하는 APC Parameter Listup 및 현재값 육안 확인
F17: 2) 좌표 값의 양수(+), 음수(-) 기준은 '오른손 좌표계'의 표준을 따른다
F18: 좌표계 기준과 X, Y, θ 실제 이동된 Offset 값 상이할 경우 APC Fail
B49: Control Parameter Check | F49: 1) 현재 APC Parameter들이 어떤 값으로 설정되어 있는지 확인한다
B51: S16F101 | F51: Current Process Control Data Request
D53: S16F102 | F53: A_PARM_NAME / VALUE가 정확히 보고되는지 확인 (설비 화면 Recipe 값과 비교)
F54: E_PARM_NAME / VALUE는 Don't Care
B56: Abnormal Case | F56: 1) 잘못된 EQPID로 조회
B58: S16F101 | F58: Current Process Control Data Request (설비 EQPID와 다른 값)
D60: S16F102 | F60: TMACK=13, Ln=0 으로 응답
B64: 10.2 Control Parameter Change
H65: Use | I65: Result
I66: 출하 검수 | J66: Line Test
H67: =COUNTIF(H70:H205, "O") -> 4 | I67: =COUNTIF(I73:I205, "O") -> 4 | J67: =COUNTIF(J70:J205, "O") -> 0
B69: Host | D69: EQ | F69: Check Item | H69: Use | I69: 출하 검수 | J69: Line Test
B70: 사전 준비 작업 | F70: 1) APC Parameter의 허용 범위를 사전에 파악한다
F71: 2) 설비의 APC Mode를 ON으로 설정한다
B73: Control Parameter Change | F73: 1) APC Parameter를 변경 가능한 값으로 변경 명령을 전송한다 | H73: O | I73: O
B75: S16F103 | F75: Process Control Information Send (변경 가능한 정상 값)
F76: ※ S16F103 CELLID 영역에 Cell ID 포함하여 전송
D77: S16F104
F79: 2) 설비는 해당 Recipe Body 중 APC Parameter를 수정/저장한다
D81: =IF(RMS!$J$13=1,"S7F217","S7F107") -> S7F217 | F81: Recipe Create/Modify/Delete Report : MODE=3 (Modify)
F82: APC Parameter 변경 요청한 값과 보고된 값이 정확히 일치하는지 확인
B84: =IF(RMS!$J$13=1,"S7F218","S7F108") -> S7F218 | F84: Recipe Create/Modify/Delete Reply
D87: S16F105 | F87: Process Control Data Change Report (MODE=1) ← MODE=1 만 사용함
F88: APC Parameter 변경 요청한 값과 보고된 값이 정확히 일치하는지 확인
F89: APC Full Parameter를 전부 보고하여야 함
...

Sheet OP Call
B1: 대외비 2020.07.13/송지훈 프로/모듈IT그룹
J2: 대외비
B3: Scenario Check List 11 - Operator Call
B5: 처음으로 | H5: Use | I5: Pass | J5: Progress
G6: 출하 검수 | H6: =H12+H39 -> 2 | I6: =I12+I39 -> 2 | J6: =I6/H6 -> 1
G7: Line Test | H7: =H6 -> 2 | I7: =J12+J39 -> 0 | J7: =I7/H7 -> 0
B9: 11.1 Operator Call
H10: Use | I10: Result
I11: 출하 검수 | J11: Line Test
H12: =COUNTIF(H15:H34, "O") -> 1 | I12: =COUNTIF(I15:I34, "O") -> 1 | J12: =COUNTIF(J15:J34, "O") -> 0
B14: Host | D14: EQ | F14: Check Item | H14: Use | I14: 출하 검수 | J14: Line Test
B16: Operator Call | F16: 1) 설비로 임의의 첫번째 Operator Call Message를 전송한다 | H16: O | I16: O
B18: S2F41 | F18: RCMD=1 : Operator Call
D20: S2F42 | F20: OP Call Popup Message
F22: 2) 설비로 임의의 두번째 Operator Call Message를 전송한다
B24: S2F41 | F24: RCMD=1 : Operator Call
D26: S2F42 | F26: OP Call Popup Message
F28: 3) Engineer가 OP Call Confirn 버튼을 누른다
D30: S6F11 | F30: CEID=501 : OP Call Confirm(EQP)
F31: Opcall이 복수개가 설비로 전달 되었을 경우 복수개 관리가 가능한 설비는
F32: 복수개 (List구조)로 Confirm 응답하고 불가능한 설비는 첫번째 Opcall로 Confirm 한다.
B33: S6F12 | F33: * 화면에 Display된 여러 개의 OP Call들이 한번에 Confirm 되어야 함
B36: 11.2 Terminal Message
H37: Use | I37: Result
I38: 출하 검수
H39: =COUNTIF(H42:H55, "O") -> 1 | I39: =COUNTIF(I42:I55, "O") -> 1 | J39: =COUNTIF(J42:J55, "O") -> 0
B41: Host | D41: EQ | F41: Check Item | H41: 대상 | I41: 사전 검수 | J41: Line Test
B43: Terminal Message | F43: 1) 설비로 임의의 첫번째 Terminal Message를 전송한다 | H43: O | I43: O
B45: S10F5 | F45: Terminal Display, TID=0
D47: S10F6 | F47: 전송한 Message가 정확히 Display되는지 확인
F49: 1) 설비로 임의의 두번째 Terminal Message를 전송한다
B51: S10F5 | F51: Terminal Display, TID=0
D53: S10F6 | F53: 전송한 Message가 정확히 Display 되는지 확인
F54: Terminal Message 이력이 Listup 되는지 확임

Sheet Interlock
B1: 대외비 2020.07.13/송지훈 프로/모듈IT그룹
J2: 대외비
B3: Scenario Check List 12 - Interlock
B5: 처음으로 | H5: Use | I5: Pass | J5: Progress
G6: 출하 검수 | H6: =H12+H122+H347 -> 2 | I6: =I12+I122+I347 -> 1 | J6: =I6/H6 -> 0.5
G7: Line Test | H7: =H6 -> 2 | I7: =J12+J122+J347 -> 0 | J7: =I7/H7 -> 0
B9: 12.1 EQP Interlock
H10: Use | I10: Result
I11: 출하 검수 | J11: Line Test
H12: =COUNTIF(H15:H117, "O") -> 2 | I12: =COUNTIF(I15:I117, "O") -> 1 | J12: =COUNTIF(J15:J117, "O") -> 0
B14: Host | D14: EQ | F14: Check Item | H14: Use | I14: 출하 검수 | J14: Line Test
F15: ※ EQP Interlock을 지원하는 설비에서 사용
F16: ※ Interlock Type은 RCMD = 12 Loading Stop Default
B17: INTERLOCK (Cycle Stop) | F17: 1) 설비에 Step Cycle Stop 명령을 내린 후 동작을 확인한다 | H17: O | I17: O
B19: S2F41 | F19: RCMD=2 : Interlcok Send
F20: MODULEID = EQPID
D22: S2F42 | F22: HOST Command Acknowledge
F23: Information Popup 창 생성 확인 (Message 내용 정합성도 확인)
F24: 설비 Step Stop 또는 Cycle Stop 발생 확인
D26: S6F11 | F26: CEID=101 : Equipment Status Change
F27: 설비 각 State 정보 확인
F28: - AVAILABILITYSTATE = UP
F29: - INTERLOCKSTATE = ON
F30: - MOVESTATE = PAUSE
F31: - RUNSTATE = RUN
B33: S6F12
F35: 2) 설비 화면에서 Interlock Confirm 실시
D37: S6F11 | F37: CEID=502 : Interlock Confirm Event
F38: 화면에 Display된 여러 개의 Interlock들이 한번에 Confirm 되어야 함
B39: S6F12 | F39: Interlock이 복수개가 설비로 전달 되었을 경우 복수개 관리가 가능한 설비는
F40: 복수개 (List구조)로 Confirm 응답하고 불가능한 설비는 첫번째 Interlock로 Confirm 한다.
F41: 이력이 설비 화면에 Interlock History 항목에 관리되어야 한다.
B43: S1F5 | F43: SFCD=1 : Equipment State
D45: S1F6 | F45: 실제 설비 화면 상 상태와 보고 내용 일치 여부 확인
B48: S1F5 | F48: SFCD=2 : Unit State
D50: S1F6 | F50: 실제 설비 화면 상 상태와 보고 내용 일치 여부 확인
F52: 3) Interlcok 발생 원인 제거 후 설비를 재가동 상태로 만든다
D54: S6F11 | F54: CEID=101 : Equipment Status Change
F55: 설비 각 State 정보 확인
F56: - AVAILABILITYSTATE = UP
...

Sheet Carrier Process
B1: 대외비 2020.07.13/송지훈 프로/모듈IT그룹
J2: 대외비
B3: Scenario Check List 15 - Carrier Process
B5: 처음으로 | H5: Use | I5: Pass | J5: Progress
G6: 출하 검수 | H6: =H29+H372+H751+H809+H1296+H1674+H1771 -> 6 | I6: =I29+I372+I751++I809+I1296+I1674+I1771 -> 6 | J6: =I6/H6 -> 1
G7: Line Test | H7: =H6 -> 6 | I7: =J29+J372+J751 -> 0 | J7: =I7/H7 -> 0
B9: ※ UI 구현 정보
B10: : Batch Lot 구성 기준 정보
B26: 15.1 Carrier Process Report For Normal Process (Loader)
H27: Use | I27: Result
I28: 출하 검수 | J28: Line Test
H29: =COUNTIF(H32:H367, "O") -> 3 | I29: =COUNTIF(I32:I367, "O") -> 3 | J29: =COUNTIF(J32:J367, "O") -> 0
B31: Host | D31: EQ | F31: Check Item | H31: Use | I31: 출하 검수 | J31: Line Test
B32: 사전 준비 작업
F33: 1. Port Manual / Auto Mode 옵션 기능 구현
F34: 2. Senser 감지 사전 확인
F35: 3. Cell이 적재된 Batch Tray 준비
B37: Carrier Release Req | F37: 1) AGV/작업자 투입 후 LI01에서 뚜껑 Tray ID Read 하고 시작 | H37: O | I37: O
F39: Tray ID Read OK
D40: S6F11 | F40: CEID=351 : Cassette Load Complete (LI01에서 ID를 Read한 시점)
F41: - PORTID : LI01
B42: S6F12 | F42: - PORTAVAILSTATE : UP (2)
F43: - PORTACCESSMODE : AUTO / MANUAL (1/0)
F44: - PORTTRANSFERSTATE : LOADED (2)
F45: - PORTPROCESSINGSTATE : READY TO PROCESS (1)
F46: - JOBID : 뚜껑 TRAY ID(Read Data)
F47: - JOB TYPE : BATCHTRAY
F49: Tray ID Read NG
F50: ※ Light Alarm 발생
F51: ※ Loader Abnormal Case 1 진행
B54: Pre Lot Validation Check | F54: 2) 뚜껑 Tray ID Read 데이터로 Carrier 정보를 요청
D56: S6F11 | F56: CEID=354 : Cassette Information Req(LI01)
F57: - Tray 정합성 Check 요청
B58: S6F12
B64: S3F115 | F64: S3F115 Carrier Information Send
F65: Batch Tray 정보 설비로 Return ReplyCode = PASS
D66: S3F116
F67: * LS01 Port가 Not Empty일 경우 대기하며 Empty일 경우나 변경 시 이동 시작
F68: - 물류 이동 시작 (LI01 -> LS01)
F69: - 물류 이동 완료 (LI01 -> LS01)
...

Sheet ETC
B1: 대외비 2020.07.13/송지훈 프로/모듈IT그룹
J2: 대외비
B3: Scenario Check List 16 - ETC
B5: 처음으로 | H5: Use | I5: Pass | J5: Progress
G6: 출하 검수 | H6: =H12+H64+H135+H207+H305+H346+H383 -> 3 | I6: =I12+I64+I135+I207+I305+I346+I383 -> 3 | J6: =I6/H6 -> 1
G7: Line Test | H7: =H6 -> 3 | I7: =J12+J64+J135+J207+J305+J346+J383 -> 0 | J7: =I7/H7 -> 0
B9: 16.1 Equipment Loss Code Report
H10: Use | I10: Result
I11: 출하 검수 | J11: Line Test
H12: =COUNTIF(H15:H59, "O") -> 1 | I12: =COUNTIF(I15:I59, "O") -> 1 | J12: =COUNTIF(J15:J59, "O") -> 0
B14: Host | D14: EQ | F14: Check Item | H14: Use | I14: 출하 검수 | J14: Line Test
B15: 사전 준비 작업 | F15: ※ 작업자가 설비를 수동으로 Stop 시켰을 때 발생한다
B17: EQ Loss Code Report | F17: 1) 작업자가 설비를 수동으로 Stop 시킨다 | H17: O | I17: O
F18: 2) CEID=606 : Equipment Loss Code Report (Eqp) 보고 하기전 설비상태를 조회한다
B20: S1F5 | F20: SFCD=1 : Equipment State
D22: S1F6
F23: 설비 각 State 정보 확인
F24: - AVAILABILITYSTATE = UP (2)
F25: - INTERLOCKSTATE = OFF (2)
F26: - MOVESTATE = RUNNING (2)
F27: - RUNSTATE = IDLE or RUN (1 or 2)
F29: 3) TPM Loss Code 선택한다
F30: CEID=606 : Equipment Loss Code Report (Eqp)
D31: S6F11 | F31: CEID=616 : Equipment Loss Code Report (Unit)
F32: LOSSCODE와 LOSSDESCRIPTION이 반드시 보고되어야 함
B33: S6F12 | F33: ※ BREAKDOWN_MANUAL 항목은 "03000"으로 보고 되어야 함
B61: 16.2 Operator Log In
H62: Use | I62: Result
I63: 출하 검수 | J63: Line Test
H64: =COUNTIF(H67:H126, "O") -> 0 | I64: =COUNTIF(I67:I126, "O") -> 0 | J64: =COUNTIF(J67:J126, "O") -> 0
B66: Host | D66: EQ | F66: Check Item | H66: Use | I66: 출하 검수 | J66: Line Test
B67: 사전 준비 작업 | F67: ※ 작업자가 Log In 하여야만 가동이 가능한 설비에 한함
B69: Log In 전 화면 제약 | F69: 1) 작업자가 Log In 하기 전에는 항상 Log In 화면이 떠 있어야 하며, 설비 동작 불가
B72: Operator Log In | F72: 1) Operator가 등록된 작업자 정보로 Log In을 시도한다
D74: S6F11 | F74: CEID=607 : Operator Information Report
F75: OPTIONINFO=LOGIN
F76: 설비 화면에 입력한 정보와 보고한 정보가 일치하는지 확인한다
B77: S6F12
B80: Log In PASS
B82: S10F5 | F82: Terminal Display (LOGIN_PASS_입력정보)
...

Sheet RMS(S7F26) Log
B1: 대외비 2020.07.13/송지훈 프로/모듈IT그룹
C2: 대외비
B3: RMS(S7F26) Log
B5: S7F26 | C5: 비고 | F5: PARAMETER NAME | G5: PARAMETER VALUE
B6: ※ 여기부터 [HH:MM:SS.mmm] RECV S7F26:S7F26 [D=] [len=] [SB=] 붙여넣기 | F6: =IFERROR(TRIM(LEFT(MID(INDIRECT("B"&(4*ROW(F6)-5)),FIND("'",INDIRECT("B"&(4*ROW(F6)-5)))+1,100),LEN(MID(INDIRECT("B"&(4*ROW(F6)-5)),FIND("'",INDIRECT("B"&(4*ROW(F6)-5)))+1,100))-2)),"") | G6: =IFERROR(LEFT(MID(INDIRECT("B"&(4*ROW(G6)-4)),FIND("'",INDIRECT("B"&(4*ROW(G6)-4)))+1,100),LEN(MID(INDIRECT("B"&(4*ROW(G6)-4)),FIND("'",INDIRECT("B"&(4*ROW(G6)-4)))+1,100))-2),"")
F7: =IFERROR(TRIM(LEFT(MID(INDIRECT("B"&(4*ROW(F7)-5)),FIND("'",INDIRECT("B"&(4*ROW(F7)-5)))+1,100),LEN(MID(INDIRECT("B"&(4*ROW(F7)-5)),FIND("'",INDIRECT("B"&(4*ROW(F7)-5)))+1,100))-2)),"") | G7: =IFERROR(LEFT(MID(INDIRECT("B"&(4*ROW(G7)-4)),FIND("'",INDIRECT("B"&(4*ROW(G7)-4)))+1,100),LEN(MID(INDIRECT("B"&(4*ROW(G7)-4)),FIND("'",INDIRECT("B"&(4*ROW(G7)-4)))+1,100))-2),"")
F8: =IFERROR(TRIM(LEFT(MID(INDIRECT("B"&(4*ROW(F8)-5)),FIND("'",INDIRECT("B"&(4*ROW(F8)-5)))+1,100),LEN(MID(INDIRECT("B"&(4*ROW(F8)-5)),FIND("'",INDIRECT("B"&(4*ROW(F8)-5)))+1,100))-2)),"") | G8: =IFERROR(LEFT(MID(INDIRECT("B"&(4*ROW(G8)-4)),FIND("'",INDIRECT("B"&(4*ROW(G8)-4)))+1,100),LEN(MID(INDIRECT("B"&(4*ROW(G8)-4)),FIND("'",INDIRECT("B"&(4*ROW(G8)-4)))+1,100))-2),"")
F9: =IFERROR(TRIM(LEFT(MID(INDIRECT("B"&(4*ROW(F9)-5)),FIND("'",INDIRECT("B"&(4*ROW(F9)-5)))+1,100),LEN(MID(INDIRECT("B"&(4*ROW(F9)-5)),FIND("'",INDIRECT("B"&(4*ROW(F9)-5)))+1,100))-2)),"") | G9: =IFERROR(LEFT(MID(INDIRECT("B"&(4*ROW(G9)-4)),FIND("'",INDIRECT("B"&(4*ROW(G9)-4)))+1,100),LEN(MID(INDIRECT("B"&(4*ROW(G9)-4)),FIND("'",INDIRECT("B"&(4*ROW(G9)-4)))+1,100))-2),"")
F10: =IFERROR(TRIM(LEFT(MID(INDIRECT("B"&(4*ROW(F10)-5)),FIND("'",INDIRECT("B"&(4*ROW(F10)-5)))+1,100),LEN(MID(INDIRECT("B"&(4*ROW(F10)-5)),FIND("'",INDIRECT("B"&(4*ROW(F10)-5)))+1,100))-2)),"") | G10: =IFERROR(LEFT(MID(INDIRECT("B"&(4*ROW(G10)-4)),FIND("'",INDIRECT("B"&(4*ROW(G10)-4)))+1,100),LEN(MID(INDIRECT("B"&(4*ROW(G10)-4)),FIND("'",INDIRECT("B"&(4*ROW(G10)-4)))+1,100))-2),"")
F11: =IFERROR(TRIM(LEFT(MID(INDIRECT("B"&(4*ROW(F11)-5)),FIND("'",INDIRECT("B"&(4*ROW(F11)-5)))+1,100),LEN(MID(INDIRECT("B"&(4*ROW(F11)-5)),FIND("'",INDIRECT("B"&(4*ROW(F11)-5)))+1,100))-2)),"") | G11: =IFERROR(LEFT(MID(INDIRECT("B"&(4*ROW(G11)-4)),FIND("'",INDIRECT("B"&(4*ROW(G11)-4)))+1,100),LEN(MID(INDIRECT("B"&(4*ROW(G11)-4)),FIND("'",INDIRECT("B"&(4*ROW(G11)-4)))+1,100))-2),"")
F12: =IFERROR(TRIM(LEFT(MID(INDIRECT("B"&(4*ROW(F12)-5)),FIND("'",INDIRECT("B"&(4*ROW(F12)-5)))+1,100),LEN(MID(INDIRECT("B"&(4*ROW(F12)-5)),FIND("'",INDIRECT("B"&(4*ROW(F12)-5)))+1,100))-2)),"") | G12: =IFERROR(LEFT(MID(INDIRECT("B"&(4*ROW(G12)-4)),FIND("'",INDIRECT("B"&(4*ROW(G12)-4)))+1,100),LEN(MID(INDIRECT("B"&(4*ROW(G12)-4)),FIND("'",INDIRECT("B"&(4*ROW(G12)-4)))+1,100))-2),"")
F13: =IFERROR(TRIM(LEFT(MID(INDIRECT("B"&(4*ROW(F13)-5)),FIND("'",INDIRECT("B"&(4*ROW(F13)-5)))+1,100),LEN(MID(INDIRECT("B"&(4*ROW(F13)-5)),FIND("'",INDIRECT("B"&(4*ROW(F13)-5)))+1,100))-2)),"") | G13: =IFERROR(LEFT(MID(INDIRECT("B"&(4*ROW(G13)-4)),FIND("'",INDIRECT("B"&(4*ROW(G13)-4)))+1,100),LEN(MID(INDIRECT("B"&(4*ROW(G13)-4)),FIND("'",INDIRECT("B"&(4*ROW(G13)-4)))+1,100))-2),"")
F14: =IFERROR(TRIM(LEFT(MID(INDIRECT("B"&(4*ROW(F14)-5)),FIND("'",INDIRECT("B"&(4*ROW(F14)-5)))+1,100),LEN(MID(INDIRECT("B"&(4*ROW(F14)-5)),FIND("'",INDIRECT("B"&(4*ROW(F14)-5)))+1,100))-2)),"") | G14: =IFERROR(LEFT(MID(INDIRECT("B"&(4*ROW(G14)-4)),FIND("'",INDIRECT("B"&(4*ROW(G14)-4)))+1,100),LEN(MID(INDIRECT("B"&(4*ROW(G14)-4)),FIND("'",INDIRECT("B"&(4*ROW(G14)-4)))+1,100))-2),"")
F15: =IFERROR(TRIM(LEFT(MID(INDIRECT("B"&(4*ROW(F15)-5)),FIND("'",INDIRECT("B"&(4*ROW(F15)-5)))+1,100),LEN(MID(INDIRECT("B"&(4*ROW(F15)-5)),FIND("'",INDIRECT("B"&(4*ROW(F15)-5)))+1,100))-2)),"") | G15: =IFERROR(LEFT(MID(INDIRECT("B"&(4*ROW(G15)-4)),FIND("'",INDIRECT("B"&(4*ROW(G15)-4)))+1,100),LEN(MID(INDIRECT("B"&(4*ROW(G15)-4)),FIND("'",INDIRECT("B"&(4*ROW(G15)-4)))+1,100))-2),"")
F16: =IFERROR(TRIM(LEFT(MID(INDIRECT("B"&(4*ROW(F16)-5)),FIND("'",INDIRECT("B"&(4*ROW(F16)-5)))+1,100),LEN(MID(INDIRECT("B"&(4*ROW(F16)-5)),FIND("'",INDIRECT("B"&(4*ROW(F16)-5)))+1,100))-2)),"") | G16: =IFERROR(LEFT(MID(INDIRECT("B"&(4*ROW(G16)-4)),FIND("'",INDIRECT("B"&(4*ROW(G16)-4)))+1,100),LEN(MID(INDIRECT("B"&(4*ROW(G16)-4)),FIND("'",INDIRECT("B"&(4*ROW(G16)-4)))+1,100))-2),"")
F17: =IFERROR(TRIM(LEFT(MID(INDIRECT("B"&(4*ROW(F17)-5)),FIND("'",INDIRECT("B"&(4*ROW(F17)-5)))+1,100),LEN(MID(INDIRECT("B"&(4*ROW(F17)-5)),FIND("'",INDIRECT("B"&(4*ROW(F17)-5)))+1,100))-2)),"") | G17: =IFERROR(LEFT(MID(INDIRECT("B"&(4*ROW(G17)-4)),FIND("'",INDIRECT("B"&(4*ROW(G17)-4)))+1,100),LEN(MID(INDIRECT("B"&(4*ROW(G17)-4)),FIND("'",INDIRECT("B"&(4*ROW(G17)-4)))+1,100))-2),"")
F18: =IFERROR(TRIM(LEFT(MID(INDIRECT("B"&(4*ROW(F18)-5)),FIND("'",INDIRECT("B"&(4*ROW(F18)-5)))+1,100),LEN(MID(INDIRECT("B"&(4*ROW(F18)-5)),FIND("'",INDIRECT("B"&(4*ROW(F18)-5)))+1,100))-2)),"") | G18: =IFERROR(LEFT(MID(INDIRECT("B"&(4*ROW(G18)-4)),FIND("'",INDIRECT("B"&(4*ROW(G18)-4)))+1,100),LEN(MID(INDIRECT("B"&(4*ROW(G18)-4)),FIND("'",INDIRECT("B"&(4*ROW(G18)-4)))+1,100))-2),"")
... F1004: =IFERROR(TRIM(LEFT(MID(INDIRECT("B"&(4*ROW(F1004)-5)),FIND("'",INDIRECT("B"&(4*ROW(F1004)-5)))+1,100),LEN(MID(INDIRECT("B"&(4*ROW(F1004)-5)),FIND("'",INDIRECT("B"&(4*ROW(F1004)-5)))+1,100))-2)),"") | G1004: =IFERROR(LEFT(MID(INDIRECT("B"&(4*ROW(G1004)-4)),FIND("'",INDIRECT("B"&(4*ROW(G1004)-4)))+1,100),LEN(MID(INDIRECT("B"&(4*ROW(G1004)-4)),FIND("'",INDIRECT("B"&(4*ROW(G1004)-4)))+1,100))-2),"")

Sheet ECM(S2F30) Log
B1: 대외비 2020.07.13/송지훈 프로/모듈IT그룹
C2: 대외비 | F2: ECID | G2: EC NAME | H2: EC NAME
B3: ECM(S2F30) Log | F3: =IFERROR(TRIM(LEFT(MID(INDIRECT("B"&(9*ROW(F3)-16)),FIND("'",INDIRECT("B"&(9*ROW(F3)-16)))+1,100),LEN(MID(INDIRECT("B"&(9*ROW(F3)-16)),FIND("'",INDIRECT("B"&(9*ROW(F3)-16)))+1,100))-2)),"") | G3: =IFERROR(LEFT(MID(INDIRECT("B"&(9*ROW(G3)-15)),FIND("'",INDIRECT("B"&(9*ROW(G3)-15)))+1,100),LEN(MID(INDIRECT("B"&(9*ROW(G3)-15)),FIND("'",INDIRECT("B"&(9*ROW(G3)-15)))+1,100))-2),"") | H3: =IFERROR(LEFT(MID(INDIRECT("B"&(9*ROW(H3)-14)),FIND("'",INDIRECT("B"&(9*ROW(H3)-14)))+1,100),LEN(MID(INDIRECT("B"&(9*ROW(H3)-14)),FIND("'",INDIRECT("B"&(9*ROW(H3)-14)))+1,100))-2),"")
C4: 'ECM' Sheet로 돌아가기 | F4: =IFERROR(TRIM(LEFT(MID(INDIRECT("B"&(9*ROW(F4)-16)),FIND("'",INDIRECT("B"&(9*ROW(F4)-16)))+1,100),LEN(MID(INDIRECT("B"&(9*ROW(F4)-16)),FIND("'",INDIRECT("B"&(9*ROW(F4)-16)))+1,100))-2)),"") | G4: =IFERROR(LEFT(MID(INDIRECT("B"&(9*ROW(G4)-15)),FIND("'",INDIRECT("B"&(9*ROW(G4)-15)))+1,100),LEN(MID(INDIRECT("B"&(9*ROW(G4)-15)),FIND("'",INDIRECT("B"&(9*ROW(G4)-15)))+1,100))-2),"") | H4: =IFERROR(LEFT(MID(INDIRECT("B"&(9*ROW(H4)-14)),FIND("'",INDIRECT("B"&(9*ROW(H4)-14)))+1,100),LEN(MID(INDIRECT("B"&(9*ROW(H4)-14)),FIND("'",INDIRECT("B"&(9*ROW(H4)-14)))+1,100))-2),"")
B5: S2F30 | C5: 비고 | F5: =IFERROR(TRIM(LEFT(MID(INDIRECT("B"&(9*ROW(F5)-16)),FIND("'",INDIRECT("B"&(9*ROW(F5)-16)))+1,100),LEN(MID(INDIRECT("B"&(9*ROW(F5)-16)),FIND("'",INDIRECT("B"&(9*ROW(F5)-16)))+1,100))-2)),"") | G5: =IFERROR(LEFT(MID(INDIRECT("B"&(9*ROW(G5)-15)),FIND("'",INDIRECT("B"&(9*ROW(G5)-15)))+1,100),LEN(MID(INDIRECT("B"&(9*ROW(G5)-15)),FIND("'",INDIRECT("B"&(9*ROW(G5)-15)))+1,100))-2),"") | H5: =IFERROR(LEFT(MID(INDIRECT("B"&(9*ROW(H5)-14)),FIND("'",INDIRECT("B"&(9*ROW(H5)-14)))+1,100),LEN(MID(INDIRECT("B"&(9*ROW(H5)-14)),FIND("'",INDIRECT("B"&(9*ROW(H5)-14)))+1,100))-2),"")
B6: ※ 여기부터 [HH:MM:SS.mmm] RECV S2F30:S2F30 [D=] [len=] [SB=] 붙여넣기 | F6: =IFERROR(TRIM(LEFT(MID(INDIRECT("B"&(9*ROW(F6)-16)),FIND("'",INDIRECT("B"&(9*ROW(F6)-16)))+1,100),LEN(MID(INDIRECT("B"&(9*ROW(F6)-16)),FIND("'",INDIRECT("B"&(9*ROW(F6)-16)))+1,100))-2)),"") | G6: =IFERROR(LEFT(MID(INDIRECT("B"&(9*ROW(G6)-15)),FIND("'",INDIRECT("B"&(9*ROW(G6)-15)))+1,100),LEN(MID(INDIRECT("B"&(9*ROW(G6)-15)),FIND("'",INDIRECT("B"&(9*ROW(G6)-15)))+1,100))-2),"") | H6: =IFERROR(LEFT(MID(INDIRECT("B"&(9*ROW(H6)-14)),FIND("'",INDIRECT("B"&(9*ROW(H6)-14)))+1,100),LEN(MID(INDIRECT("B"&(9*ROW(H6)-14)),FIND("'",INDIRECT("B"&(9*ROW(H6)-14)))+1,100))-2),"")
F7: =IFERROR(TRIM(LEFT(MID(INDIRECT("B"&(9*ROW(F7)-16)),FIND("'",INDIRECT("B"&(9*ROW(F7)-16)))+1,100),LEN(MID(INDIRECT("B"&(9*ROW(F7)-16)),FIND("'",INDIRECT("B"&(9*ROW(F7)-16)))+1,100))-2)),"") | G7: =IFERROR(LEFT(MID(INDIRECT("B"&(9*ROW(G7)-15)),FIND("'",INDIRECT("B"&(9*ROW(G7)-15)))+1,100),LEN(MID(INDIRECT("B"&(9*ROW(G7)-15)),FIND("'",INDIRECT("B"&(9*ROW(G7)-15)))+1,100))-2),"") | H7: =IFERROR(LEFT(MID(INDIRECT("B"&(9*ROW(H7)-14)),FIND("'",INDIRECT("B"&(9*ROW(H7)-14)))+1,100),LEN(MID(INDIRECT("B"&(9*ROW(H7)-14)),FIND("'",INDIRECT("B"&(9*ROW(H7)-14)))+1,100))-2),"")
F8: =IFERROR(TRIM(LEFT(MID(INDIRECT("B"&(9*ROW(F8)-16)),FIND("'",INDIRECT("B"&(9*ROW(F8)-16)))+1,100),LEN(MID(INDIRECT("B"&(9*ROW(F8)-16)),FIND("'",INDIRECT("B"&(9*ROW(F8)-16)))+1,100))-2)),"") | G8: =IFERROR(LEFT(MID(INDIRECT("B"&(9*ROW(G8)-15)),FIND("'",INDIRECT("B"&(9*ROW(G8)-15)))+1,100),LEN(MID(INDIRECT("B"&(9*ROW(G8)-15)),FIND("'",INDIRECT("B"&(9*ROW(G8)-15)))+1,100))-2),"") | H8: =IFERROR(LEFT(MID(INDIRECT("B"&(9*ROW(H8)-14)),FIND("'",INDIRECT("B"&(9*ROW(H8)-14)))+1,100),LEN(MID(INDIRECT("B"&(9*ROW(H8)-14)),FIND("'",INDIRECT("B"&(9*ROW(H8)-14)))+1,100))-2),"")
F9: =IFERROR(TRIM(LEFT(MID(INDIRECT("B"&(9*ROW(F9)-16)),FIND("'",INDIRECT("B"&(9*ROW(F9)-16)))+1,100),LEN(MID(INDIRECT("B"&(9*ROW(F9)-16)),FIND("'",INDIRECT("B"&(9*ROW(F9)-16)))+1,100))-2)),"") | G9: =IFERROR(LEFT(MID(INDIRECT("B"&(9*ROW(G9)-15)),FIND("'",INDIRECT("B"&(9*ROW(G9)-15)))+1,100),LEN(MID(INDIRECT("B"&(9*ROW(G9)-15)),FIND("'",INDIRECT("B"&(9*ROW(G9)-15)))+1,100))-2),"") | H9: =IFERROR(LEFT(MID(INDIRECT("B"&(9*ROW(H9)-14)),FIND("'",INDIRECT("B"&(9*ROW(H9)-14)))+1,100),LEN(MID(INDIRECT("B"&(9*ROW(H9)-14)),FIND("'",INDIRECT("B"&(9*ROW(H9)-14)))+1,100))-2),"")
F10: =IFERROR(TRIM(LEFT(MID(INDIRECT("B"&(9*ROW(F10)-16)),FIND("'",INDIRECT("B"&(9*ROW(F10)-16)))+1,100),LEN(MID(INDIRECT("B"&(9*ROW(F10)-16)),FIND("'",INDIRECT("B"&(9*ROW(F10)-16)))+1,100))-2)),"") | G10: =IFERROR(LEFT(MID(INDIRECT("B"&(9*ROW(G10)-15)),FIND("'",INDIRECT("B"&(9*ROW(G10)-15)))+1,100),LEN(MID(INDIRECT("B"&(9*ROW(G10)-15)),FIND("'",INDIRECT("B"&(9*ROW(G10)-15)))+1,100))-2),"") | H10: =IFERROR(LEFT(MID(INDIRECT("B"&(9*ROW(H10)-14)),FIND("'",INDIRECT("B"&(9*ROW(H10)-14)))+1,100),LEN(MID(INDIRECT("B"&(9*ROW(H10)-14)),FIND("'",INDIRECT("B"&(9*ROW(H10)-14)))+1,100))-2),"")
F11: =IFERROR(TRIM(LEFT(MID(INDIRECT("B"&(9*ROW(F11)-16)),FIND("'",INDIRECT("B"&(9*ROW(F11)-16)))+1,100),LEN(MID(INDIRECT("B"&(9*ROW(F11)-16)),FIND("'",INDIRECT("B"&(9*ROW(F11)-16)))+1,100))-2)),"") | G11: =IFERROR(LEFT(MID(INDIRECT("B"&(9*ROW(G11)-15)),FIND("'",INDIRECT("B"&(9*ROW(G11)-15)))+1,100),LEN(MID(INDIRECT("B"&(9*ROW(G11)-15)),FIND("'",INDIRECT("B"&(9*ROW(G11)-15)))+1,100))-2),"") | H11: =IFERROR(LEFT(MID(INDIRECT("B"&(9*ROW(H11)-14)),FIND("'",INDIRECT("B"&(9*ROW(H11)-14)))+1,100),LEN(MID(INDIRECT("B"&(9*ROW(H11)-14)),FIND("'",INDIRECT("B"&(9*ROW(H11)-14)))+1,100))-2),"")
F12: =IFERROR(TRIM(LEFT(MID(INDIRECT("B"&(9*ROW(F12)-16)),FIND("'",INDIRECT("B"&(9*ROW(F12)-16)))+1,100),LEN(MID(INDIRECT("B"&(9*ROW(F12)-16)),FIND("'",INDIRECT("B"&(9*ROW(F12)-16)))+1,100))-2)),"") | G12: =IFERROR(LEFT(MID(INDIRECT("B"&(9*ROW(G12)-15)),FIND("'",INDIRECT("B"&(9*ROW(G12)-15)))+1,100),LEN(MID(INDIRECT("B"&(9*ROW(G12)-15)),FIND("'",INDIRECT("B"&(9*ROW(G12)-15)))+1,100))-2),"") | H12: =IFERROR(LEFT(MID(INDIRECT("B"&(9*ROW(H12)-14)),FIND("'",INDIRECT("B"&(9*ROW(H12)-14)))+1,100),LEN(MID(INDIRECT("B"&(9*ROW(H12)-14)),FIND("'",INDIRECT("B"&(9*ROW(H12)-14)))+1,100))-2),"")
